Workbook

Sheet PO Set Target attain level
D1: PO-CO Mapping (Targetted Level) - Course Articulation Matrix
C3: Course Name : | D3: DATABASE MANAGEMENT SYSTEM
C4: Course Code : | D4: 22319
C5: Program/Scheme-MSBTE Inst.code : | D5: 3rd SEM(CO3I SCHEME)
C6: Academic Year : | D6: 2023-24
B7: Course Outcomes :
C8: CO1 | D8: Design Normalized database on given data..
C9: CO2 | D9: Create and Manage Database using SQL command
C10: CO3 | D10: Write PL/SQL code for given database
C11: CO4 | D11: Apply triggers ob database also create procedure and function according to condition.
C12: CO5 | D12: Apply security and confidentiality on given Database..
B15: Set Correlation of CO-PO Mapping
B16: Strength of correlation : 3 - high (Substantial), 2- medium (moderate) , 1- low, No relation : '-'
B17: Sr. No. | C17: CO | E17: PO | L17: PSO
E18: PO1 | F18: PO2 | G18: PO3 | H18: PO4 | I18: PO5 | J18: PO6 | K18: PO7 | L18: PSO1 | M18: PSO2
E19: Basic Knowledge & Discipline Knowledge | F19: Problem analysis | G19: Design/developmet of solutions | H19: Engineering tools, Experimentation and Testing | I19: Engineering Practices for society, sustainability , Environment, Ethics | J19: Project Management | K19: Life Long learning | L19: Computer Software and Hardware Usage | M19: Computer Engineering Maintenance
B20: 1 | C20: =C8 -> CO1 | D20: =D8 -> Design Normalized database on given data.. | E20: 3 | F20: 2 | G20: 3 | H20: 1 | I20: 1 | J20: - | K20: 1 | L20: 3 | M20: 2
B21: 2 | C21: =C9 -> CO2 | D21: =D9 -> Create and Manage Database using SQL command | E21: 3 | F21: 2 | G21: 2 | H21: 2 | I21: 3 | J21: - | K21: 1 | L21: 3 | M21: 2
B22: 3 | C22: =C10 -> CO3 | D22: =D10 -> Write PL/SQL code for given database | E22: 3 | F22: 2 | G22: 2 | H22: 1 | I22: 3 | J22: - | K22: 1 | L22: 3 | M22: 2
B23: 4 | C23: =C11 -> CO4 | D23: =D11 -> Apply triggers ob database also create procedure and function according to condition. | E23: 2 | F23: 3 | G23: 3 | H23: 2 | I23: 2 | J23: - | K23: 1 | L23: 2 | M23: 3
B24: 5 | C24: =C12 -> CO5 | D24: =D12 -> Apply security and confidentiality on given Database.. | E24: 2 | F24: 1 | G24: 1 | H24: 1 | I24: 2 | J24: 1 | K24: 2 | L24: 2 | M24: 1
D25: =D13 -> 0
B26: Average | E26: =IFERROR(AVERAGE(E20:E24),2) -> 2.6 | F26: =IFERROR(AVERAGE(F20:F24),2) -> 2 | G26: =IFERROR(AVERAGE(G20:G24),2) -> 2.2 | H26: =IFERROR(AVERAGE(H20:H24),2) -> 1.4 | I26: =IFERROR(AVERAGE(I20:I24),2) -> 2.2 | J26: =IFERROR(AVERAGE(J20:J24),2) -> 1 | K26: =IFERROR(AVERAGE(K20:K24),2) -> 1.2 | L26: =IFERROR(AVERAGE(L20:L24),2) -> 2.6 | M26: =IFERROR(AVERAGE(M20:M24),2) -> 2
B27: Targeted Attainment Level | E27: =E26 -> 2.6 | F27: =F26 -> 2 | G27: =G26 -> 2.2 | H27: =H26 -> 1.4 | I27: =I26 -> 2.2 | J27: =J26 -> 1 | K27: =K26 -> 1.2 | L27: =L26 -> 2.6 | M27: =M26 -> 2
D30: HOD COMPUTER | I30: Name of Faculty & Signature
C31: GOVERNMENT POLYTECHNIC DHARASHIV | I31: GOVERNMENT POLYTECHNIC DHARASHIV
B35: Note : | D35: Fill only this colour cells for all worksheets
D36: This cells are autofilled fields . Do not overwrite this cells for all worksheets

Sheet CO_Attainment for Unit Tests
A1: Evaluation of Answersheets for FA-TH(Unit Test)
A2: Internal Assessment ( Direct Mode)
B3: Course Name : | C3: ='PO Set Target attain level'!D3 -> DATABASE MANAGEMENT SYSTEM
B4: Course Code : | C4: ='PO Set Target attain level'!D4 -> 22319
B5: Program/Semester : | C5: ='PO Set Target attain level'!D5 -> 3rd SEM(CO3I SCHEME)
B6: Academic Year | C6: ='PO Set Target attain level'!D6 -> 2023-24
A8: Sr. No. | B8: Enrollment ID / Seat No | C8: Student Name | D8: CO1 max. Marks | E8: CO2 max. Marks | F8: CO3 max. Marks | G8: CO4 max. Marks | H8: CO5 max. Marks | I8: CO6 max. Marks | J8: U. TEST I | K8: U. TEST II
J9: Total Max. Marks(with Extra)
D12: 16 | E12: 16 | F12: 12 | G12: 10 | H12: 10 | J12: =SUM(D12:E12) -> 32 | K12: =SUM(F12:H12) -> 32
A13: 1 | B13: 2201180002 | C13: GARAD ANJALI NITIN | D13: 5 | E13: 4 | F13: 2 | G13: 2 | H13: 3 | J13: =SUM(D13:E13) -> 9 | K13: =SUM(F13:H13) -> 7
A14: 2 | B14: 2201180003 | C14: WALANDE GAURI DAYANAND | D14: 12 | E14: 8 | F14: 6 | G14: 8 | H14: 6 | J14: =SUM(D14:E14) -> 20 | K14: =SUM(F14:H14) -> 20
A15: 3 | B15: 2201180004 | C15: ZUNJURE SARTHAK BALAJI | D15: 12 | E15: 12 | F15: 11 | G15: 8 | H15: 5 | J15: =SUM(D15:E15) -> 24 | K15: =SUM(F15:H15) -> 24
A16: 4 | B16: 2201180005 | C16: BHANDE GAYATRI DAMODAR | D16: 15 | E16: 13 | F16: 12 | G16: 10 | H16: 7 | J16: =SUM(D16:E16) -> 28 | K16: =SUM(F16:H16) -> 29
A17: 5 | B17: 2201180006 | C17: MUNDHE GAYATRI PARMESHWAR | D17: 15 | E17: 8 | F17: 6 | G17: 10 | H17: 6 | J17: =SUM(D17:E17) -> 23 | K17: =SUM(F17:H17) -> 22
A18: 6 | B18: 2201180009 | C18: YADAV RADHA SAMADHAN | D18: 12 | E18: 6 | F18: 4 | G18: 7 | H18: 5 | J18: =SUM(D18:E18) -> 18 | K18: =SUM(F18:H18) -> 16
A19: 7 | B19: 2201180010 | C19: DESHMANE MANSI SIDDHESHWAR | D19: 13 | E19: 10 | F19: 11 | G19: 10 | H19: 5 | J19: =SUM(D19:E19) -> 23 | K19: =SUM(F19:H19) -> 26
A20: 8 | B20: 2201180011 | C20: GAWALGADADE POOJA ARVIND | D20: 8 | E20: 3 | F20: 6 | G20: 7 | H20: 3 | J20: =SUM(D20:E20) -> 11 | K20: =SUM(F20:H20) -> 16
A21: 9 | B21: 2201180014 | C21: JAIN TANISHA SHAILESH | D21: 11 | E21: 4 | F21: 8 | G21: 7 | H21: 2 | J21: =SUM(D21:E21) -> 15 | K21: =SUM(F21:H21) -> 17
A22: 10 | B22: 2201180050 | C22: MAINDARGE SIDDHI PRASAD | D22: 11 | E22: 6 | F22: 4 | G22: 7 | H22: 6 | J22: =SUM(D22:E22) -> 17 | K22: =SUM(F22:H22) -> 17
A23: 11 | B23: 2201180051 | C23: BHOSALE VAISHNAVI DAYANAND | D23: 14 | E23: 9 | F23: 8 | G23: 8 | H23: 6 | J23: =SUM(D23:E23) -> 23 | K23: =SUM(F23:H23) -> 22
A24: 12 | B24: 2201180052 | C24: ATTAR SANIYA VAJIR | D24: 15 | E24: 7 | F24: 7 | G24: 8 | H24: 2 | J24: =SUM(D24:E24) -> 22 | K24: =SUM(F24:H24) -> 17
... A74: 62 | B74: 23510250264 | C74: VHOTTE SHRUTIKA VAIJNATH | D74: 0 | E74: 0 | F74: 0 | G74: 0 | H74: 0 | J74: =SUM(D74:E74) -> 0 | K74: =SUM(F74:H74) -> 0
A75: 63 | J75: =SUM(D75:E75) -> 0 | K75: =SUM(F75:H75) -> 0
A76: 64 | J76: =SUM(D76:E76) -> 0 | K76: =SUM(F76:H76) -> 0
A77: 65 | J77: =SUM(D77:E77) -> 0 | K77: =SUM(F77:H77) -> 0
A78: 66 | J78: =SUM(D78:E78) -> 0 | K78: =SUM(F78:H78) -> 0
A79: 67 | J79: =SUM(D79:E79) -> 0 | K79: =SUM(F79:H79) -> 0
A80: 68 | J80: =SUM(D80:E80) -> 0 | K80: =SUM(F80:H80) -> 0
A81: 69 | J81: =SUM(D81:E81) -> 0 | K81: =SUM(F81:H81) -> 0
A82: 70 | J82: =SUM(D82:E82) -> 0 | K82: =SUM(F82:H82) -> 0
A83: 71 | J83: =SUM(D83:E83) -> 0 | K83: =SUM(F83:H83) -> 0
A84: 72 | J84: =SUM(D84:E84) -> 0 | K84: =SUM(F84:H84) -> 0
A85: 73 | J85: =SUM(D85:E85) -> 0 | K85: =SUM(F85:H85) -> 0
A86: 74 | J86: =SUM(D86:E86) -> 0 | K86: =SUM(F86:H86) -> 0
... A89: 77 | J89: =SUM(D89:E89) -> 0 | K89: =SUM(F89:H89) -> 0
A90: 78 | J90: =SUM(D90:F90) -> 0 | K90: =SUM(G90:I90) -> 0
A91: 79 | J91: =SUM(D91:F91) -> 0 | K91: =SUM(G91:I91) -> 0
A92: 80 | J92: =SUM(D92:F92) -> 0 | K92: =SUM(G92:I92) -> 0
A93: 81 | J93: =SUM(D93:F93) -> 0 | K93: =SUM(G93:I93) -> 0
A94: 82 | J94: =SUM(D94:F94) -> 0 | K94: =G94+H94+I94 -> 0
...

Sheet CO_attainment for FA-TH ESE
B1: External Evaluation of End Semester Board Examination
D2: Direct Assessment
C4: Course Name : | D4: ='CO_Attainment for Unit Tests'!C3 -> DATABASE MANAGEMENT SYSTEM
C5: Course Code : | D5: ='CO_Attainment for Unit Tests'!C4 -> 22319
C6: Program/Semester : | D6: ='CO_Attainment for Unit Tests'!C5 -> 3rd SEM(CO3I SCHEME)
C7: Academic Year : | D7: ='CO_Attainment for Unit Tests'!C6 -> 2023-24
B9: Sr. No. | C9: Enrollment ID / Seat No | D9: Student Name | E9: TH-ESE (End Sem Board Exam.) Max. Marks
E13: 70
B14: 1 | C14: ='CO_Attainment for Unit Tests'!B13 -> 2201180002 | D14: ='CO_Attainment for Unit Tests'!C13 -> GARAD ANJALI NITIN | E14: 10
B15: 2 | C15: ='CO_Attainment for Unit Tests'!B14 -> 2201180003 | D15: ='CO_Attainment for Unit Tests'!C14 -> WALANDE GAURI DAYANAND | E15: 51
B16: 3 | C16: ='CO_Attainment for Unit Tests'!B15 -> 2201180004 | D16: ='CO_Attainment for Unit Tests'!C15 -> ZUNJURE SARTHAK BALAJI | E16: 45
B17: 4 | C17: ='CO_Attainment for Unit Tests'!B16 -> 2201180005 | D17: ='CO_Attainment for Unit Tests'!C16 -> BHANDE GAYATRI DAMODAR | E17: 56
B18: 5 | C18: ='CO_Attainment for Unit Tests'!B17 -> 2201180006 | D18: ='CO_Attainment for Unit Tests'!C17 -> MUNDHE GAYATRI PARMESHWAR | E18: 54
B19: 6 | C19: ='CO_Attainment for Unit Tests'!B18 -> 2201180009 | D19: ='CO_Attainment for Unit Tests'!C18 -> YADAV RADHA SAMADHAN | E19: 41
B20: 7 | C20: ='CO_Attainment for Unit Tests'!B19 -> 2201180010 | D20: ='CO_Attainment for Unit Tests'!C19 -> DESHMANE MANSI SIDDHESHWAR | E20: 45
B21: 8 | C21: ='CO_Attainment for Unit Tests'!B20 -> 2201180011 | D21: ='CO_Attainment for Unit Tests'!C20 -> GAWALGADADE POOJA ARVIND | E21: 30
B22: 9 | C22: ='CO_Attainment for Unit Tests'!B21 -> 2201180014 | D22: ='CO_Attainment for Unit Tests'!C21 -> JAIN TANISHA SHAILESH | E22: 51
B23: 10 | C23: ='CO_Attainment for Unit Tests'!B22 -> 2201180050 | D23: ='CO_Attainment for Unit Tests'!C22 -> MAINDARGE SIDDHI PRASAD | E23: 51
B24: 11 | C24: ='CO_Attainment for Unit Tests'!B23 -> 2201180051 | D24: ='CO_Attainment for Unit Tests'!C23 -> BHOSALE VAISHNAVI DAYANAND | E24: 41
B25: 12 | C25: ='CO_Attainment for Unit Tests'!B24 -> 2201180052 | D25: ='CO_Attainment for Unit Tests'!C24 -> ATTAR SANIYA VAJIR | E25: 54
... B75: 62 | C75: ='CO_Attainment for Unit Tests'!B74 -> 23510250264 | D75: ='CO_Attainment for Unit Tests'!C74 -> VHOTTE SHRUTIKA VAIJNATH | E75: 0
B76: 63 | C76: ='CO_Attainment for Unit Tests'!B75 -> 0 | D76: ='CO_Attainment for Unit Tests'!C75 -> 0
B77: 64 | C77: ='CO_Attainment for Unit Tests'!B76 -> 0 | D77: ='CO_Attainment for Unit Tests'!C76 -> 0
B78: 65 | C78: ='CO_Attainment for Unit Tests'!B77 -> 0 | D78: ='CO_Attainment for Unit Tests'!C77 -> 0
B79: 66 | C79: ='CO_Attainment for Unit Tests'!B78 -> 0 | D79: ='CO_Attainment for Unit Tests'!C78 -> 0
B80: 67 | C80: ='CO_Attainment for Unit Tests'!B78 -> 0 | D80: ='CO_Attainment for Unit Tests'!C75 -> 0
B81: 68 | C81: ='CO_Attainment for Unit Tests'!B79 -> 0 | D81: ='CO_Attainment for Unit Tests'!C76 -> 0
B82: 69 | C82: ='CO_Attainment for Unit Tests'!B80 -> 0 | D82: ='CO_Attainment for Unit Tests'!C77 -> 0
B83: 70 | C83: ='CO_Attainment for Unit Tests'!B81 -> 0 | D83: ='CO_Attainment for Unit Tests'!C78 -> 0
B84: 71 | C84: ='CO_Attainment for Unit Tests'!B82 -> 0 | D84: ='CO_Attainment for Unit Tests'!C82 -> 0
B85: 72 | C85: ='CO_Attainment for Unit Tests'!B83 -> 0 | D85: ='CO_Attainment for Unit Tests'!C83 -> 0
B86: 73 | C86: ='CO_Attainment for Unit Tests'!B84 -> 0 | D86: ='CO_Attainment for Unit Tests'!C84 -> 0
B87: 74 | C87: ='CO_Attainment for Unit Tests'!B85 -> 0 | D87: ='CO_Attainment for Unit Tests'!C85 -> 0
B88: 75 | C88: ='CO_Attainment for Unit Tests'!B86 -> 0 | D88: ='CO_Attainment for Unit Tests'!C86 -> 0
B89: 76 | C89: ='CO_Attainment for Unit Tests'!B87 -> 0 | D89: ='CO_Attainment for Unit Tests'!C87 -> 0
B90: 77 | C90: ='CO_Attainment for Unit Tests'!B88 -> 0 | D90: ='CO_Attainment for Unit Tests'!C88 -> 0
B91: 78 | C91: ='CO_Attainment for Unit Tests'!B89 -> 0 | D91: ='CO_Attainment for Unit Tests'!C89 -> 0
B92: 79 | C92: ='CO_Attainment for Unit Tests'!B90 -> 0 | D92: ='CO_Attainment for Unit Tests'!C90 -> 0
B93: 80 | C93: ='CO_Attainment for Unit Tests'!B91 -> 0 | D93: ='CO_Attainment for Unit Tests'!C91 -> 0
B94: 81 | C94: ='CO_Attainment for Unit Tests'!B92 -> 0 | D94: ='CO_Attainment for Unit Tests'!C92 -> 0
...

Sheet CO_attain_SLA_FA-PR_SA-PR
D1: Internal Evaluation of PA-Practical work, Micro-Project, PR-ESE
E2: Direct Assessment
C4: Course Name : | D4: ='CO_Attainment for Unit Tests'!C3 -> DATABASE MANAGEMENT SYSTEM
C5: Course Code : | D5: ='CO_Attainment for Unit Tests'!C4 -> 22319
C6: Program/Semester : | D6: ='CO_Attainment for Unit Tests'!C5 -> 3rd SEM(CO3I SCHEME)
C7: Academic Year: | D7: ='CO_Attainment for Unit Tests'!C6 -> 2023-24
B9: Sr. No. | C9: Enrollment ID / Seat No | D9: Student Name | E9: (Micro Project/Assignment Evaluation (max. marks ) | F9: PR-PA | G9: PR-ESE
E13: 10 | F13: 25 | G13: 25
B14: 1 | C14: ='CO_Attainment for Unit Tests'!B13 -> 2201180002 | D14: ='CO_Attainment for Unit Tests'!C13 -> GARAD ANJALI NITIN | E14: 6 | F14: 22 | G14: 20
B15: 2 | C15: ='CO_Attainment for Unit Tests'!B14 -> 2201180003 | D15: ='CO_Attainment for Unit Tests'!C14 -> WALANDE GAURI DAYANAND | E15: 8 | F15: 23 | G15: 22
B16: 3 | C16: ='CO_Attainment for Unit Tests'!B15 -> 2201180004 | D16: ='CO_Attainment for Unit Tests'!C15 -> ZUNJURE SARTHAK BALAJI | E16: 7 | F16: 23 | G16: 22
B17: 4 | C17: ='CO_Attainment for Unit Tests'!B16 -> 2201180005 | D17: ='CO_Attainment for Unit Tests'!C16 -> BHANDE GAYATRI DAMODAR | E17: 8 | F17: 23 | G17: 23
B18: 5 | C18: ='CO_Attainment for Unit Tests'!B17 -> 2201180006 | D18: ='CO_Attainment for Unit Tests'!C17 -> MUNDHE GAYATRI PARMESHWAR | E18: 9 | F18: 23 | G18: 23
B19: 6 | C19: ='CO_Attainment for Unit Tests'!B18 -> 2201180009 | D19: ='CO_Attainment for Unit Tests'!C18 -> YADAV RADHA SAMADHAN | E19: 7 | F19: 23 | G19: 21
B20: 7 | C20: ='CO_Attainment for Unit Tests'!B19 -> 2201180010 | D20: ='CO_Attainment for Unit Tests'!C19 -> DESHMANE MANSI SIDDHESHWAR | E20: 6 | F20: 23 | G20: 22
B21: 8 | C21: ='CO_Attainment for Unit Tests'!B20 -> 2201180011 | D21: ='CO_Attainment for Unit Tests'!C20 -> GAWALGADADE POOJA ARVIND | E21: 6 | F21: 23 | G21: 21
B22: 9 | C22: ='CO_Attainment for Unit Tests'!B21 -> 2201180014 | D22: ='CO_Attainment for Unit Tests'!C21 -> JAIN TANISHA SHAILESH | E22: 7 | F22: 23 | G22: 22
B23: 10 | C23: ='CO_Attainment for Unit Tests'!B22 -> 2201180050 | D23: ='CO_Attainment for Unit Tests'!C22 -> MAINDARGE SIDDHI PRASAD | E23: 7 | F23: 23 | G23: 21
B24: 11 | C24: ='CO_Attainment for Unit Tests'!B23 -> 2201180051 | D24: ='CO_Attainment for Unit Tests'!C23 -> BHOSALE VAISHNAVI DAYANAND | E24: 8 | F24: 23 | G24: 22
B25: 12 | C25: ='CO_Attainment for Unit Tests'!B24 -> 2201180052 | D25: ='CO_Attainment for Unit Tests'!C24 -> ATTAR SANIYA VAJIR | E25: 7 | F25: 24 | G25: 22
... B75: 62 | C75: ='CO_Attainment for Unit Tests'!B74 -> 23510250264 | D75: ='CO_Attainment for Unit Tests'!C74 -> VHOTTE SHRUTIKA VAIJNATH | E75: 0 | F75: 0 | G75: 0
B76: 63
B77: 64
B78: 65
B79: 66
B80: 67
B81: 68
B82: 69
B83: 70
B84: 71
B85: 72
B86: 73
B87: 74
... B96: 83
D97: Set Competency target as % marks for each criteria | E97: =ROUNDUP(D98*E13/100,1) -> 6 | F97: =ROUNDUP(D98*F13/100,1) -> 15 | G97: =ROUNDUP(D98*G13/100,1) -> 15
D98: 60
D99: No. of students above set target | E99: =COUNTIF(E14:E96,">=" &E97) -> 58 | F99: =COUNTIF(F14:F96,">=" &F97) -> 58 | G99: =COUNTIF(G14:G96,">=" &G97) -> 59
B103: Benchmark of Attainment level against set target/ competency for above criteria | E103: No of Students | G103: Level
B104: LEVEL | C104: 0.5 | D104: of Students got more than set target | E104: =COUNTA(D14:D96)-COUNTIFS(D14:D96,0) -> 62 | F104: =C104*$E104 -> 31 | G104: 1
C105: 0.6 | D105: of Students got more than set target | F105: =C105*$E104 -> 37.2 | G105: 2
...

Sheet CO_attainment for Indirect
C1: Indirect Assessment through Course end Survey
C4: Course Name : | D4: ='CO_attain_SLA_FA-PR_SA-PR'!D4 -> DATABASE MANAGEMENT SYSTEM
C5: Course Code : | D5: ='CO_attain_SLA_FA-PR_SA-PR'!D5 -> 22319
C6: Program/Semester : | D6: ='CO_attain_SLA_FA-PR_SA-PR'!D6 -> 3rd SEM(CO3I SCHEME)
C7: Academic Year: | D7: ='CO_attain_SLA_FA-PR_SA-PR'!D7 -> 2023-24
B9: * Rating Scale : 5-Excellent, 4-Very good, 3- Good, 2-poor, 1-Very Poor
B10: Sr. No. | C10: Enrollment ID | D10: Student Name | E10: # Course Exit Survey of students ( * Rating Scale )
E14: 5
B15: 1 | C15: ='CO_attainment for FA-TH ESE'!C14 -> 2201180002 | D15: ='CO_attainment for FA-TH ESE'!D14 -> GARAD ANJALI NITIN | E15: 0
C16: ='CO_attainment for FA-TH ESE'!#REF! -> #REF! | D16: ='CO_attainment for FA-TH ESE'!#REF! -> #REF!
B17: 2 | C17: ='CO_attainment for FA-TH ESE'!#REF! -> #REF! | D17: ='CO_attainment for FA-TH ESE'!#REF! -> #REF!
C18: ='CO_attainment for FA-TH ESE'!#REF! -> #REF! | D18: ='CO_attainment for FA-TH ESE'!#REF! -> #REF!
B19: 3 | C19: ='CO_attainment for FA-TH ESE'!#REF! -> #REF! | D19: ='CO_attainment for FA-TH ESE'!#REF! -> #REF!
C20: ='CO_attainment for FA-TH ESE'!#REF! -> #REF! | D20: ='CO_attainment for FA-TH ESE'!#REF! -> #REF!
C21: ='CO_attainment for FA-TH ESE'!#REF! -> #REF! | D21: ='CO_attainment for FA-TH ESE'!#REF! -> #REF!
B22: 4 | C22: ='CO_attainment for FA-TH ESE'!#REF! -> #REF! | D22: ='CO_attainment for FA-TH ESE'!#REF! -> #REF!
C23: ='CO_attainment for FA-TH ESE'!#REF! -> #REF! | D23: ='CO_attainment for FA-TH ESE'!#REF! -> #REF!
C24: ='CO_attainment for FA-TH ESE'!#REF! -> #REF! | D24: ='CO_attainment for FA-TH ESE'!#REF! -> #REF!
C25: ='CO_attainment for FA-TH ESE'!#REF! -> #REF! | D25: ='CO_attainment for FA-TH ESE'!#REF! -> #REF!
C26: ='CO_attainment for FA-TH ESE'!#REF! -> #REF! | D26: ='CO_attainment for FA-TH ESE'!#REF! -> #REF!
C27: ='CO_attainment for FA-TH ESE'!#REF! -> #REF! | D27: ='CO_attainment for FA-TH ESE'!#REF! -> #REF!
C28: ='CO_attainment for FA-TH ESE'!#REF! -> #REF! | D28: ='CO_attainment for FA-TH ESE'!#REF! -> #REF!
C29: ='CO_attainment for FA-TH ESE'!#REF! -> #REF! | D29: ='CO_attainment for FA-TH ESE'!#REF! -> #REF!
C30: ='CO_attainment for FA-TH ESE'!#REF! -> #REF! | D30: ='CO_attainment for FA-TH ESE'!#REF! -> #REF!
B31: 5 | C31: ='CO_attainment for FA-TH ESE'!#REF! -> #REF! | D31: ='CO_attainment for FA-TH ESE'!#REF! -> #REF!
C32: ='CO_attainment for FA-TH ESE'!#REF! -> #REF! | D32: ='CO_attainment for FA-TH ESE'!#REF! -> #REF!
C33: ='CO_attainment for FA-TH ESE'!#REF! -> #REF! | D33: ='CO_attainment for FA-TH ESE'!#REF! -> #REF!
C34: ='CO_attainment for FA-TH ESE'!#REF! -> #REF! | D34: ='CO_attainment for FA-TH ESE'!#REF! -> #REF!
C35: ='CO_attainment for FA-TH ESE'!#REF! -> #REF! | D35: ='CO_attainment for FA-TH ESE'!#REF! -> #REF!
C36: ='CO_attainment for FA-TH ESE'!#REF! -> #REF! | D36: ='CO_attainment for FA-TH ESE'!#REF! -> #REF!
C37: ='CO_attainment for FA-TH ESE'!#REF! -> #REF! | D37: ='CO_attainment for FA-TH ESE'!#REF! -> #REF!
B38: 6 | C38: ='CO_attainment for FA-TH ESE'!#REF! -> #REF! | D38: ='CO_attainment for FA-TH ESE'!#REF! -> #REF!
C39: ='CO_attainment for FA-TH ESE'!#REF! -> #REF! | D39: ='CO_attainment for FA-TH ESE'!#REF! -> #REF!
C40: ='CO_attainment for FA-TH ESE'!#REF! -> #REF! | D40: ='CO_attainment for FA-TH ESE'!#REF! -> #REF!
C41: ='CO_attainment for FA-TH ESE'!#REF! -> #REF! | D41: ='CO_attainment for FA-TH ESE'!#REF! -> #REF!
C42: ='CO_attainment for FA-TH ESE'!#REF! -> #REF! | D42: ='CO_attainment for FA-TH ESE'!#REF! -> #REF!
C43: ='CO_attainment for FA-TH ESE'!#REF! -> #REF! | D43: ='CO_attainment for FA-TH ESE'!#REF! -> #REF!
C44: ='CO_attainment for FA-TH ESE'!#REF! -> #REF! | D44: ='CO_attainment for FA-TH ESE'!#REF! -> #REF!
C45: ='CO_attainment for FA-TH ESE'!#REF! -> #REF! | D45: ='CO_attainment for FA-TH ESE'!#REF! -> #REF!
C46: ='CO_attainment for FA-TH ESE'!#REF! -> #REF! | D46: ='CO_attainment for FA-TH ESE'!#REF! -> #REF!
...

Sheet CO_PO Mapping Attainment 
F1: CO -PO Attainment
C4: Set Corelation of CO-PO Mapping
C5: Strength of corelation : 3 - high (Substantial), 2- medium, 1- low
B6: Sr. No. | C6: CO | E6: PO | O6: PSO
E7: PO1 | F7: PO2 | G7: PO3 | H7: PO4 | I7: PO5 | J7: PO6 | K7: PO7 | L7: PO8 | M7: PO9 | N7: PO10 | O7: PSO1 | P7: PSO2
E8: Basic Knowledge | F8: Discipline Knowledge | G8: Experiments and Practice | H8: Engineering tools | I8: The Engineer and Society | J8: Environment and Sustainability | K8: Ethics | L8: Individual and Team work | M8: Communication | N8: Life-long learning | O8: Modern software Usage | P8: Measurement of mechanical equipments
B9: 1 | C9: CO1 | D9: Apply the laws of thermodynamics to devices based on thermodynamics | E9: 3 | F9: 3 | G9: 2 | H9: 2 | I9: 2 | J9: 2 | K9: 2 | L9: 2 | M9: 2 | N9: 3 | O9: 3 | P9: 2
B10: 2 | C10: CO2 | D10: Use first law of thermodynamic for ideal gas in closed systems | E10: 3 | F10: 3 | G10: 1 | H10: 2 | I10: 2 | J10: 2 | K10: 2 | L10: 2 | M10: 2 | N10: 1 | O10: 2 | P10: 2
B11: 3 | C11: CO3 | D11: Use relevant steam boilers | E11: 3 | F11: 3 | G11: 2 | H11: 2 | I11: 2 | J11: 3 | K11: 2 | L11: 3 | M11: 2 | N11: 2 | O11: 2 | P11: 2
B12: 4 | C12: CO4 | D12: Use relevant steam nozzles and turbines | E12: 3 | F12: 3 | G12: 2 | H12: 3 | I12: 3 | J12: 2 | K12: 3 | L12: 2 | M12: 2 | N12: 3 | O12: 2 | P12: 2
B13: 5 | C13: CO5 | D13: Use relevant steam condensers | E13: 3 | F13: 3 | G13: 3 | H13: 3 | I13: 2 | J13: 2 | K13: 1 | L13: 3 | M13: 2 | N13: 2 | O13: 3 | P13: 3
B14: 6 | C14: CO6 | D14: Use suitable modes for heat transfer | E14: 3 | F14: 3 | G14: 2 | H14: 2 | I14: 1 | J14: 2 | K14: 1 | L14: 1 | M14: 2 | N14: 1 | O14: 2 | P14: 2
B15: Contribution to PO | E15: =ROUNDUP(AVERAGE(E9:E14),2) -> 3 | F15: =ROUNDUP(AVERAGE(F9:F14),2) -> 3 | G15: =ROUNDUP(AVERAGE(G9:G14),2) -> 2 | H15: =ROUNDUP(AVERAGE(H9:H14),2) -> 2.34 | I15: =ROUNDUP(AVERAGE(I9:I14),2) -> 2 | J15: =ROUNDUP(AVERAGE(J9:J14),2) -> 2.17 | K15: =ROUNDUP(AVERAGE(K9:K14),2) -> 1.84 | L15: =ROUNDUP(AVERAGE(L9:L14),2) -> 2.17 | ... P15: =ROUNDUP(AVERAGE(P9:P14),2) -> 2.17
B16: Course-PO attainment | E16: =ROUNDUP((E15*2.66)/3,2) -> 2.66 | F16: =ROUNDUP((F15*2.66)/3,2) -> 2.66 | G16: =ROUNDUP((G15*2.66)/3,2) -> 1.78 | H16: =ROUNDUP((H15*2.66)/3,2) -> 2.08 | I16: =ROUNDUP((I15*2.66)/3,2) -> 1.78 | J16: =ROUNDUP((J15*2.66)/3,2) -> 1.93 | K16: =ROUNDUP((K15*2.66)/3,2) -> 1.64 | L16: =ROUNDUP((L15*2.66)/3,2) -> 1.93 | ... P16: =ROUNDUP((P15*2.66)/3,2) -> 1.93
B17: % Course-PO attainment | E17: =ROUNDUP((E16/3)*100,2) -> 88.67 | F17: =ROUNDUP((F16/3)*100,2) -> 88.67 | G17: =ROUNDUP((G16/3)*100,2) -> 59.34 | H17: =ROUNDUP((H16/3)*100,2) -> 69.34 | I17: =ROUNDUP((I16/3)*100,2) -> 59.34 | J17: =ROUNDUP((J16/3)*100,2) -> 64.34 | K17: =ROUNDUP((K16/3)*100,2) -> 54.67 | L17: =ROUNDUP((L16/3)*100,2) -> 64.34 | ... P17: =ROUNDUP((P16/3)*100,2) -> 64.34

Sheet Overall CO attainment (2)
E1: Overall CO Attainment
C3: Course Name : | D3: ='CO_attainment for Indirect'!D4 -> DATABASE MANAGEMENT SYSTEM
C4: Course Code : | D4: ='CO_attainment for Indirect'!D5 -> 22319
C5: Program/Semester : | D5: ='CO_attainment for Indirect'!D6 -> 3rd SEM(CO3I SCHEME)
C6: Academic Year: | D6: ='CO_attain_SLA_FA-PR_SA-PR'!D7 -> 2023-24
C8: Overall Course CO Attainment
C9: Final Direct Course Attainment Calculation | I9: Final Indirect Course Attainment Calculation
C10: COS | D10: Internal | H10: External
D11: Unit Tests | E11: PA_Term Work | F11: Micro- Project | G11: PR-ESE | H11: E.S.E Board | I11: Course Exit Survey
C12: CO1 | D12: ='CO_Attainment for Unit Tests'!D109 -> 3 | E12: ='CO_attain_SLA_FA-PR_SA-PR'!C111 -> 3 | F12: ='CO_attain_SLA_FA-PR_SA-PR'!C110 -> 3 | G12: ='CO_attain_SLA_FA-PR_SA-PR'!C112 -> 3 | H12: ='CO_attainment for FA-TH ESE'!C110 -> 3 | I12: ='CO_attainment for Indirect'!C91 -> 0
C13: CO2 | D13: ='CO_Attainment for Unit Tests'!E109 -> 2 | E13: =$E12 -> 3 | F13: =$F12 -> 3 | G13: =$G12 -> 3 | H13: =$H12 -> 3 | I13: =$I12 -> 0
C14: CO3 | D14: ='CO_Attainment for Unit Tests'!F109 -> 3 | E14: =$E13 -> 3 | F14: =$F13 -> 3 | G14: =$G13 -> 3 | H14: =$H13 -> 3 | I14: =$I13 -> 0
C15: CO4 | D15: ='CO_Attainment for Unit Tests'!G109 -> 3 | E15: =$E14 -> 3 | F15: =$F14 -> 3 | G15: =$G14 -> 3 | H15: =$H14 -> 3 | I15: =$I14 -> 0
C16: CO5 | D16: ='CO_Attainment for Unit Tests'!H109 -> 2 | E16: =$E15 -> 3 | F16: =$F15 -> 3 | G16: =$G15 -> 3 | H16: =$H15 -> 3 | I16: =$I15 -> 0
C17: CO6 | D17: ='CO_Attainment for Unit Tests'!I109 -> 0 | E17: =$E16 -> 3 | F17: =$F16 -> 3 | G17: =$G16 -> 3 | H17: =$H16 -> 3 | I17: =$I16 -> 0
C18: Average Attainment | D18: =ROUND(AVERAGE(D12:D17),2) -> 2.17 | E18: =ROUND(AVERAGE(E12:E17),2) -> 3 | F18: =ROUND(AVERAGE(F12:F17),2) -> 3 | G18: =ROUND(AVERAGE(G12:G17),2) -> 3 | H18: =ROUND(AVERAGE(H12:H17),2) -> 3 | I18: =ROUND(AVERAGE(I12:I17),2) -> 0
C19: Indiviual Weightage (%) | D19: 10 | E19: 10 | F19: 10 | G19: 10 | H19: 60 | I19: 100
C20: Direct Total Attainment | D20: =D18*D19/100 -> 0.217 | E20: =E18*E19/100 -> 0.3 | F20: =F18*F19/100 -> 0.3 | G20: =G18*G19/100 -> 0.3 | H20: =H18*H19/100 -> 1.8 | I20: =I18*I19/100 -> 0
C21: Total Direct Course Attainment | H21: =SUM(D20:H20) -> 2.917 | I21: Total Indirect Course Attainment | J21: =I20 -> 0
C22: Overall Weightage | H22: 0.8 | I22: Weightage | J22: 0.2
C23: Final Direct Course Attainment | H23: =0.8*H21 -> 2.3336 | I23: Final Indirect Course Attainment | J23: =0.2*J21 -> 0
C24: Overall Course CO Attainment (B) | I24: =ROUNDUP(H23+J23,2) -> 2.34
G30: Template sheet is Prepared by Prof. A.B.Bhure
G31: L.M.E., P.L.G.P. Latur

Sheet Overall CO attainment
E1: Overall CO Attainment
C3: Course Name : | D3: ='CO_attainment for Indirect'!D4 -> DATABASE MANAGEMENT SYSTEM
C4: Course Code : | D4: ='CO_attainment for Indirect'!D5 -> 22319
C5: Program/Semester : | D5: ='CO_attainment for Indirect'!D6 -> 3rd SEM(CO3I SCHEME)
C6: Academic Year: | D6: ='CO_attain_SLA_FA-PR_SA-PR'!D7 -> 2023-24
C8: DIRECT CO ASSESSMENT TOOL/COURSE EVALUATION PLAN | E8: TH-PA | H8: PR-PA | I8: PR-ESE | J8: TH-ESE | K8: TOTAL
E9: U.Test I | F9: U. Test II | G9: Microproject | H9: PA_Term Work | I9: Practical Exam | J9: E.S.E Board
C10: MAX MARKS AS PER TEACHING SCHEME | E10: 20 | G10: 10 | H10: 25 | I10: 25 | J10: 70 | K10: =SUM(E10:J10) -> 150
C11: INDIVIDUAL WEIGHTAGE (%) | E11: =(E10/$K10)*100 -> 13.333333 | G11: =(G10/$K10)*100 -> 6.6666667 | H11: =(H10/$K10)*100 -> 16.666667 | I11: =(I10/$K10)*100 -> 16.666667 | J11: =(J10/$K10)*100 -> 46.666667 | K11: =SUM(E11:J11) -> 100
C15: Overall Course CO Attainment
C16: Final Direct Course Attainment Calculation
C17: COS | E17: Internal | H17: External
D18: Unit Tests | E18: PA_Term Work | F18: Micro- Project | G18: PR-ESE | H18: E.S.E Board
C19: CO1 | D19: ='CO_Attainment for Unit Tests'!D109 -> 3 | E19: ='CO_attain_SLA_FA-PR_SA-PR'!C111 -> 3 | F19: ='CO_attain_SLA_FA-PR_SA-PR'!C110 -> 3 | G19: ='CO_attain_SLA_FA-PR_SA-PR'!C112 -> 3 | H19: ='CO_attainment for FA-TH ESE'!C110 -> 3
C20: CO2 | D20: ='CO_Attainment for Unit Tests'!E109 -> 2 | E20: =$E19 -> 3 | F20: =$F19 -> 3 | G20: =$G19 -> 3 | H20: =$H19 -> 3
C21: CO3 | D21: ='CO_Attainment for Unit Tests'!F109 -> 3 | E21: =$E20 -> 3 | F21: =$F20 -> 3 | G21: =$G20 -> 3 | H21: =$H20 -> 3
C22: CO4 | D22: ='CO_Attainment for Unit Tests'!G109 -> 3 | E22: =$E21 -> 3 | F22: =$F21 -> 3 | G22: =$G21 -> 3 | H22: =$H21 -> 3
C23: CO5 | D23: ='CO_Attainment for Unit Tests'!H109 -> 2 | E23: =$E22 -> 3 | F23: =$F22 -> 3 | G23: =$G22 -> 3 | H23: =$H22 -> 3
C24: CO6 | D24: ='CO_Attainment for Unit Tests'!I109 -> 0 | E24: =$E23 -> 3 | F24: =$F23 -> 3 | G24: =$G23 -> 3 | H24: =$H23 -> 3
C25: Average Attainment | D25: =ROUND(AVERAGE(D19:D24),2) -> 2.17 | E25: =ROUND(AVERAGE(E19:E24),2) -> 3 | F25: =ROUND(AVERAGE(F19:F24),2) -> 3 | G25: =ROUND(AVERAGE(G19:G24),2) -> 3 | H25: =ROUND(AVERAGE(H19:H24),2) -> 3
C26: Indiviual Weightage (%) | D26: =E11 -> 13.333333 | E26: =H11 -> 16.666667 | F26: =G11 -> 6.6666667 | G26: =I11 -> 16.666667 | H26: =J11 -> 46.666667
C27: Direct Total Attainment | D27: =D25*D26/100 -> 0.28933333 | E27: =E25*E26/100 -> 0.5 | F27: =F25*F26/100 -> 0.2 | G27: =G25*G26/100 -> 0.5 | H27: =H25*H26/100 -> 1.4
C28: Total Direct Course Attainment | H28: =SUM(D27:H27) -> 2.8893333
C29: Overall Weightage | H29: 1
C30: Final Direct Course Attainment | H30: =H29*H28 -> 2.8893333
C31: Overall Course CO Attainment (B) | I31: =H30+J30 -> 2.8893333
H34: Name of Faculty & Signature
H35: GOVERNMENT POLYTECHNIC DHARASHIV

Sheet CO_PO Mapping Attainment_PO7
E1: CO -PO Actual Attainment
C2: Course Name : | D2: ='Overall CO attainment'!D3 -> DATABASE MANAGEMENT SYSTEM
C3: Course Code : | D3: ='Overall CO attainment'!D4 -> 22319
C4: Program/Scheme-MSBTE Inst.code : | D4: ='Overall CO attainment'!D5 -> 3rd SEM(CO3I SCHEME)
C5: Academic Year: | D5: ='Overall CO attainment'!D6 -> 2023-24
B8: Strength of correlation : 3 - high (Substantial), 2- medium(moderate), 1- low, No relation : '-'
B9: Sr. No. | C9: CO | E9: PO | L9: PSO
E10: PO1 | F10: PO2 | G10: PO3 | H10: PO4 | I10: PO5 | J10: PO6 | K10: PO7 | L10: PSO1 | M10: PSO2
E11: Basic Knowledge & Discipline Knowledge | F11: Problem analysis | G11: Design/developmet of solutions | H11: Engineering tools, Experimentation and Testing | I11: Engineering Practices for society, sustainability , Environment, Ethics | J11: Project Management | K11: Life Long learning | L11: Computer Software and Hardware Usage | M11: Computer Engineering Maintenance
B12: ='PO Set Target attain level'!B20 -> 1 | C12: ='PO Set Target attain level'!C20 -> CO1 | D12: ='PO Set Target attain level'!D20 -> Design Normalized database on given data.. | E12: ='PO Set Target attain level'!E20 -> 3 | F12: ='PO Set Target attain level'!F20 -> 2 | G12: ='PO Set Target attain level'!G20 -> 3 | H12: ='PO Set Target attain level'!H20 -> 1 | I12: ='PO Set Target attain level'!I20 -> 1 | ... M12: ='PO Set Target attain level'!M20 -> 2
B13: ='PO Set Target attain level'!B21 -> 2 | C13: ='PO Set Target attain level'!C21 -> CO2 | D13: ='PO Set Target attain level'!D21 -> Create and Manage Database using SQL command | E13: ='PO Set Target attain level'!E21 -> 3 | F13: ='PO Set Target attain level'!F21 -> 2 | G13: ='PO Set Target attain level'!G21 -> 2 | H13: ='PO Set Target attain level'!H21 -> 2 | I13: ='PO Set Target attain level'!I21 -> 3 | ... M13: ='PO Set Target attain level'!M21 -> 2
B14: ='PO Set Target attain level'!B22 -> 3 | C14: ='PO Set Target attain level'!C22 -> CO3 | D14: ='PO Set Target attain level'!D22 -> Write PL/SQL code for given database | E14: ='PO Set Target attain level'!E22 -> 3 | F14: ='PO Set Target attain level'!F22 -> 2 | G14: ='PO Set Target attain level'!G22 -> 2 | H14: ='PO Set Target attain level'!H22 -> 1 | I14: ='PO Set Target attain level'!I22 -> 3 | ... M14: ='PO Set Target attain level'!M22 -> 2
B15: ='PO Set Target attain level'!B23 -> 4 | C15: ='PO Set Target attain level'!C23 -> CO4 | D15: ='PO Set Target attain level'!D23 -> Apply triggers ob database also create procedure and function according to condition. | E15: ='PO Set Target attain level'!E23 -> 2 | F15: ='PO Set Target attain level'!F23 -> 3 | G15: ='PO Set Target attain level'!G23 -> 3 | H15: ='PO Set Target attain level'!H23 -> 2 | I15: ='PO Set Target attain level'!I23 -> 2 | ... M15: ='PO Set Target attain level'!M23 -> 3
B16: ='PO Set Target attain level'!B24 -> 5 | C16: ='PO Set Target attain level'!C24 -> CO5 | D16: ='PO Set Target attain level'!D24 -> Apply security and confidentiality on given Database.. | F16: ='PO Set Target attain level'!F24 -> 1 | G16: ='PO Set Target attain level'!G24 -> 1 | H16: ='PO Set Target attain level'!H24 -> 1 | I16: ='PO Set Target attain level'!I24 -> 2 | J16: ='PO Set Target attain level'!J24 -> 1 | K16: ='PO Set Target attain level'!K24 -> 2 | L16: ='PO Set Target attain level'!L24 -> 2 | M16: ='PO Set Target attain level'!M24 -> 1
B17: Average Contribution of each CO to each PO (A) | E17: =IFERROR(AVERAGE(E12:E16),0) -> 2.75 | F17: =IFERROR(AVERAGE(F12:F16),0) -> 2 | G17: =IFERROR(AVERAGE(G12:G16),0) -> 2.2 | H17: =IFERROR(AVERAGE(H12:H16),0) -> 1.4 | I17: =IFERROR(AVERAGE(I12:I16),0) -> 2.2 | J17: =IFERROR(AVERAGE(J12:J16),0) -> 1 | K17: =IFERROR(AVERAGE(K12:K16),0) -> 1.2 | L17: =IFERROR(AVERAGE(L12:L16),0) -> 2.6 | M17: =IFERROR(AVERAGE(M12:M16),0) -> 2
B18: Course CO-PO ACTUAL ATTAINMENT LEVEL= ((AxB)/3) | E18: =E17*'Overall CO attainment'!I31/3 -> 2.6485556 | F18: =F17*'Overall CO attainment'!I31/3 -> 1.9262222 | G18: =G17*'Overall CO attainment'!I31/3 -> 2.1188444 | H18: =H17*'Overall CO attainment'!I31/3 -> 1.3483556 | I18: =I17*'Overall CO attainment'!I31/3 -> 2.1188444 | J18: =J17*'Overall CO attainment'!I31/3 -> 0.96311111 | K18: =K17*'Overall CO attainment'!I31/3 -> 1.1557333 | L18: =L17*'Overall CO attainment'!I31/3 -> 2.5040889 | M18: =M17*'Overall CO attainment'!I31/3 -> 1.9262222
B19: % Course-PO attainment | E19: =ROUNDUP((E18/3)*100,2) -> 88.29 | F19: =ROUNDUP((F18/3)*100,2) -> 64.21 | G19: =ROUNDUP((G18/3)*100,2) -> 70.63 | H19: =ROUNDUP((H18/3)*100,2) -> 44.95 | I19: =ROUNDUP((I18/3)*100,2) -> 70.63 | J19: =ROUNDUP((J18/3)*100,2) -> 32.11 | K19: =ROUNDUP((K18/3)*100,2) -> 38.53 | L19: =ROUNDUP((L18/3)*100,2) -> 83.47 | M19: =ROUNDUP((M18/3)*100,2) -> 64.21
J22: Name of Faculty & Signature
J23: GOVERNMENT POLYTECHNIC DHARASHIV

Sheet Justification
B2: CO | C2: PO1 | D2: PO2 | E2: PO3 | F2: PO4 | G2: PO5 | H2: PO6 | I2: PO7 | J2: PSO1 | K2: PSO2
B3: CO1 | C3: 3 | D3: 2 | E3: 3 | F3: 1 | G3: 1 | H3: - | I3: 1 | J3: 3 | K3: 2
B4: CO2 | C4: 3 | D4: 2 | E4: 2 | F4: 2 | G4: 3 | H4: - | I4: 1 | J4: 3 | K4: 2
B5: CO3 | C5: 3 | D5: 2 | E5: 2 | F5: 1 | G5: 3 | H5: - | I5: 1 | J5: 3 | K5: 2
B6: CO4 | C6: 2 | D6: 3 | E6: 3 | F6: 2 | G6: 2 | H6: - | I6: 1 | J6: 2 | K6: 3
B7: CO5 | C7: 2 | D7: 1 | E7: 1 | F7: 1 | G7: 2 | H7: 1 | I7: 2 | J7: 2 | K7: 1 | X7: UT1
X8: 1 | Y8: a | Z8: 2 | AA8: 2 | AB8: 2 | AC8: 2 | AD8: 4 | AE8: 4 | AF8: =SUM(Z8:AE8) -> 16
T9: 22319 | U9: 100 | V9: 70 | X9: 2 | Y9: b | Z9: 2 | AA9: 2 | AB9: 4 | AC9: 4 | AD9: 4 | AF9: =SUM(Z9:AE9) -> 16
B10: Correlation to Program Outcomes (POs) | T10: MSBTE TSI | U10: 54.24 | V10: =ROUNDUP((U10*70)/100,2) -> 37.97 | X10: 3 | Y10: c | AF10: =SUM(Z10:AE10) -> 0
X11: 4 | Y11: d | AF11: =SUM(Z11:AE11) -> 0
B12: PO1: Basic Knowledge: Database design and SQL are core computer science fundamentals. All COs have a strong (3) correlation here as they form the foundation of data storage. | X12: 5 | Y12: e | AF12: =SUM(Z12:AE12) -> 0
AF13: =SUM(AF8:AF12) -> 32
B14: PO2: Problem Analysis: Mapping real-world data to a database (CO1) and applying triggers/procedures for conditions (CO4) requires identifying and analyzing user requirements.
U15: 37.97
B16: PO3: Design/Development of Solutions: Designing a normalized database (CO1) and creating stored procedures/functions (CO4) are direct design-and-develop tasks.
X17: ut2
B18: PO4: Engineering Tools: Using SQL interfaces and DBMS software (CO2, CO4) aligns with utilizing engineering tools for experimentation. | X18: 1 | Y18: a | AF18: =SUM(Z18:AE18) -> 0
X19: 2 | Y19: b | AF19: =SUM(Z19:AE19) -> 0
B20: PO5: Engineering Practices (Ethics/Environment): Applying security and confidentiality (CO5) directly maps to engineering ethics, specifically data privacy and security practices. | X20: 3 | Y20: c | Z20: 2 | AA20: 2 | AB20: 4 | AC20: 4 | AF20: =SUM(Z20:AE20) -> 12
X21: 4 | Y21: d | Z21: 2 | AA21: 2 | AB21: 2 | AC21: 4 | AF21: =SUM(Z21:AE21) -> 10
B22: 2. Correlation to Program Specific Outcomes (PSOs) | X22: 5 | Y22: e | Z22: 2 | AA22: 4 | AB22: 4 | AF22: =SUM(Z22:AE22) -> 10
AF23: =SUM(AF18:AF22) -> 32
B24: PSO1: Computer Software & Hardware Usage: DBMS is the backbone of most software applications. Mastering SQL, normalization, and PL/SQL is essential for building any software system.
B26: PSO2: Computer Engineering Maintenance: Managing a database (CO2) and optimizing it through procedures and security measures (CO4, CO5) is critical for system maintenance and operational efficiency.
