Workbook

Sheet PO Set Target attain level
D1: PO-CO Mapping (Targetted Level) - Course Articulation Matrix
C3: Course Name : | D3: SEMINAR AND PROJECT INITIATION COURSE
C4: Course Code : | D4: 315003
C5: Program/Scheme-MSBTE Inst.code : | D5: 5th Sem Co5K K-Scheme
C6: Academic Year : | D6: 2025-26
B7: Course Outcomes :
C8: CO1 | D8: Identify topics of seminar presenting to the large gathering at the institute/conference.
C9: CO2 | D9: Collect relevant and updated research-based data and information to prepare a paper of seminar presentation.
C10: CO3 | D10: Apply presentation skills.
C11: CO4 | D11: Create conducive environment for learning and discussion through seminar presentation.
C12: CO5 | D12: Identify a problem statement and establish the action plan for the successful completion of the project.
B14: Set Correlation of CO-PO Mapping
B15: Strength of correlation : 3 - high (Substantial), 2- medium (moderate) , 1- low, No relation : '-'
B16: Sr. No. | C16: CO | E16: PO | L16: PSO
E17: PO1 | F17: PO2 | G17: PO3 | H17: PO4 | I17: PO5 | J17: PO6 | K17: PO7 | L17: PSO1 | M17: PSO2
E18: Basic Knowledge & Discipline Knowledge | F18: Problem analysis | G18: Design/developmet of solutions | H18: Engineering tools, Experimentation and Testing | I18: Engineering Practices for society, sustainability , Environment, Ethics | J18: Project Management | K18: Life Long learning | L18: Computer Software and Hardware Usage | M18: Computer Engineering Maintenance
B19: 1 | C19: =C8 -> CO1 | D19: =D8 -> Identify topics of seminar presenting to the large gathering at the institute/conference. | E19: 3 | F19: 1 | G19: - | H19: - | I19: 2 | J19: 2 | K19: 3 | L19: 1 | M19: -
B20: 2 | C20: =C9 -> CO2 | D20: =D9 -> Collect relevant and updated research-based data and information to prepare a paper of seminar presentation. | E20: 2 | F20: - | G20: 2 | H20: - | I20: 2 | J20: 1 | K20: 3 | L20: 2 | M20: 1
B21: 3 | C21: =C10 -> CO3 | D21: =D10 -> Apply presentation skills. | E21: 3 | F21: 1 | G21: 1 | H21: 2 | I21: 1 | J21: 2 | K21: 3 | L21: 1 | M21: -
B22: 4 | C22: =C11 -> CO4 | D22: =D11 -> Create conducive environment for learning and discussion through seminar presentation. | E22: 2 | F22: - | G22: - | H22: 2 | I22: 1 | J22: 2 | K22: 3 | L22: - | M22: -
B23: 5 | C23: =C12 -> CO5 | D23: =D12 -> Identify a problem statement and establish the action plan for the successful completion of the project. | E23: 3 | F23: 3 | G23: 3 | H23: 2 | I23: 2 | J23: 3 | K23: 3 | L23: 2 | M23: 3
B24: Average | E24: =IFERROR(AVERAGE(E19:E23),2) -> 2.6 | F24: =IFERROR(AVERAGE(F19:F23),2) -> 1.6666667 | G24: =IFERROR(AVERAGE(G19:G23),2) -> 2 | H24: =IFERROR(AVERAGE(H19:H23),2) -> 2 | I24: =IFERROR(AVERAGE(I19:I23),2) -> 1.6 | J24: =IFERROR(AVERAGE(J19:J23),2) -> 2 | K24: =IFERROR(AVERAGE(K19:K23),2) -> 3 | L24: =IFERROR(AVERAGE(L19:L23),2) -> 1.5 | M24: =IFERROR(AVERAGE(M19:M23),2) -> 2
B25: Targeted Attainment Level | E25: =E24 -> 2.6 | F25: =F24 -> 1.6666667 | G25: =G24 -> 2 | H25: =H24 -> 2 | I25: =I24 -> 1.6 | J25: =J24 -> 2 | K25: =K24 -> 3 | L25: =L24 -> 1.5 | M25: =M24 -> 2
D28: HOD Computer | I28: Name of Faculty & Signature
C29: GOVERNMENT POLYTECHNIC DHARASHIV | I29: GOVERNMENT POLYTECHNIC DHARASHIV
B33: Note : | D33: Fill only this colour cells for all worksheets
D34: This cells are autofilled fields . Do not overwrite this cells for all worksheets

Sheet CO_Attainment for Unit Tests
A1: Evaluation of Answersheets for FA-TH(Unit Test)
A2: Internal Assessment ( Direct Mode)
B3: Course Name : | C3: ='PO Set Target attain level'!D3 -> SEMINAR AND PROJECT INITIATION COURSE
B4: Course Code : | C4: ='PO Set Target attain level'!D4 -> 315003
B5: Program/Semester : | C5: ='PO Set Target attain level'!D5 -> 5th Sem Co5K K-Scheme
B6: Academic Year | C6: ='PO Set Target attain level'!D6 -> 2025-26
A8: Sr. No. | B8: Enrollment ID / Seat No | C8: Student Name | D8: CO1 max. Marks | E8: CO2 max. Marks | F8: CO3 max. Marks | G8: CO4 max. Marks | H8: CO5 max. Marks | I8: CO6 max. Marks | J8: U. TEST I | K8: U. TEST II
J9: Total Max. Marks(with Extra)
D12: 8 | E12: 12 | F12: 8 | G12: 8 | H12: 12 | I12: 8 | J12: =D12+E12+F12 -> 28 | K12: =G12+H12+I12 -> 28
A13: 1 | B13: 2201180008 | C13: DHANSHETTI PRIYA SANJAY | J13: =D13+E13+F13 -> 0 | K13: =G13+H13+I13 -> 0
A14: 2 | B14: 23510250191 | C14: ADSUL SHASHWATI NITIN | J14: =D14+E14+F14 -> 0 | K14: =G14+H14+I14 -> 0
A15: 3 | B15: 23510250192 | C15: AVISHKAR BABRUWAN BHISE | J15: =D15+E15+F15 -> 0 | K15: =G15+H15+I15 -> 0
A16: 4 | B16: 23510250193 | C16: AWAD MAHESHWARI BHAU | J16: =D16+E16+F16 -> 0 | K16: =G16+H16+I16 -> 0
A17: 5 | B17: 23510250194 | C17: BADVE SHARVANI DNYANESHWAR | J17: =D17+E17+F17 -> 0 | K17: =G17+H17+I17 -> 0
A18: 6 | B18: 23510250195 | C18: BAGADE MANASI MUKUND | J18: =D18+E18+F18 -> 0 | K18: =G18+H18+I18 -> 0
A19: 7 | B19: 23510250196 | C19: BARDE ARCHANA HANUMANT | J19: =D19+E19+F19 -> 0 | K19: =G19+H19+I19 -> 0
A20: 8 | B20: 23510250197 | C20: BARMADE SHRADDHA SUDHAKAR | J20: =D20+E20+F20 -> 0 | K20: =G20+H20+I20 -> 0
A21: 9 | B21: 23510250198 | C21: BEDKE ANKITA SHRIRAM | J21: =D21+E21+F21 -> 0 | K21: =G21+H21+I21 -> 0
A22: 10 | B22: 23510250199 | C22: BHAD SHRAVANI UMAKANT | J22: =D22+E22+F22 -> 0 | K22: =G22+H22+I22 -> 0
A23: 11 | B23: 23510250200 | C23: BHORE NIKITA SHANKAR | J23: =D23+E23+F23 -> 0 | K23: =G23+H23+I23 -> 0
A24: 12 | B24: 23510250201 | C24: BHOSALE PRADNYA HARIDAS | J24: =D24+E24+F24 -> 0 | K24: =G24+H24+I24 -> 0
... A75: 63 | B75: 24510250266 | C75: WAWALKAR ANJALI ANIL | J75: =D75+E75+F75 -> 0 | K75: =G75+H75+I75 -> 0
A76: 64 | J76: =D76+E76+F76 -> 0 | K76: =G76+H76+I76 -> 0
A77: 65 | J77: =D77+E77+F77 -> 0 | K77: =G77+H77+I77 -> 0
A78: 66 | J78: =D78+E78+F78 -> 0 | K78: =G78+H78+I78 -> 0
A79: 67 | J79: =D79+E79+F79 -> 0 | K79: =G79+H79+I79 -> 0
A80: 68 | J80: =D80+E80+F80 -> 0 | K80: =G80+H80+I80 -> 0
A81: 69 | J81: =D81+E81+F81 -> 0 | K81: =G81+H81+I81 -> 0
A82: 70 | J82: =D82+E82+F82 -> 0 | K82: =G82+H82+I82 -> 0
A83: 71 | J83: =D83+E83+F83 -> 0 | K83: =G83+H83+I83 -> 0
A84: 72 | J84: =D84+E84+F84 -> 0 | K84: =G84+H84+I84 -> 0
A85: 73 | J85: =D85+E85+F85 -> 0 | K85: =G85+H85+I85 -> 0
A86: 74 | J86: =D86+E86+F86 -> 0 | K86: =G86+H86+I86 -> 0
A87: 75 | J87: =D87+E87+F87 -> 0 | K87: =G87+H87+I87 -> 0
... A95: 83 | J95: =D95+E95+F95 -> 0 | K95: =G95+H95+I95 -> 0
A96: #Set Competency target as % marks of max marks for each CO -- > | C96: 0.4 | D96: =$C$96*D12 -> 3.2 | E96: =$C$96*E12 -> 4.8 | F96: =$C$96*F12 -> 3.2 | G96: =$C$96*G12 -> 3.2 | H96: =$C$96*H12 -> 4.8 | I96: =$C$96*I12 -> 3.2
A97: No. of students above set target
D98: =COUNTIF(D13:D95,">=" &D96) -> 0 | E98: =COUNTIF(E13:E95,">=" &E96) -> 0 | F98: =COUNTIF(F13:F95,">=" &F96) -> 0 | G98: =COUNTIF(G13:G95,">=" &G96) -> 0 | H98: =COUNTIF(H13:H95,">=" &H96) -> 0 | I98: =COUNTIF(I13:I95,">=" &I96) -> 0
B103: Benchmark of Attainment level against set target/ competency | F103: No of Students | I103: Level
B104: LEVEL | C104: 50 % of Students got more than set target --> | E104: 50 | F104: 63 | H104: =E104*F104/100 -> 31.5 | I104: 1
...

Sheet CO_attainment for FA-TH ESE
B1: External Evaluation of End Semester Board Examination
D2: Direct Assessment
C4: Course Name : | D4: ='CO_Attainment for Unit Tests'!C3 -> SEMINAR AND PROJECT INITIATION COURSE
C5: Course Code : | D5: ='CO_Attainment for Unit Tests'!C4 -> 315003
C6: Program/Semester : | D6: ='CO_Attainment for Unit Tests'!C5 -> 5th Sem Co5K K-Scheme
C7: Academic Year : | D7: ='CO_Attainment for Unit Tests'!C6 -> 2025-26
B9: Sr. No. | C9: Enrollment ID / Seat No | D9: Student Name | E9: SA-TH (End Sem Board Exam.) Max. Marks
E13: 70
B14: 1 | C14: ='CO_Attainment for Unit Tests'!B13 -> 2201180008 | D14: ='CO_Attainment for Unit Tests'!C13 -> DHANSHETTI PRIYA SANJAY
B15: 2 | C15: ='CO_Attainment for Unit Tests'!B14 -> 23510250191 | D15: ='CO_Attainment for Unit Tests'!C14 -> ADSUL SHASHWATI NITIN
B16: 3 | C16: ='CO_Attainment for Unit Tests'!B15 -> 23510250192 | D16: ='CO_Attainment for Unit Tests'!C15 -> AVISHKAR BABRUWAN BHISE
B17: 4 | C17: ='CO_Attainment for Unit Tests'!B16 -> 23510250193 | D17: ='CO_Attainment for Unit Tests'!C16 -> AWAD MAHESHWARI BHAU
B18: 5 | C18: ='CO_Attainment for Unit Tests'!B17 -> 23510250194 | D18: ='CO_Attainment for Unit Tests'!C17 -> BADVE SHARVANI DNYANESHWAR
B19: 6 | C19: ='CO_Attainment for Unit Tests'!B18 -> 23510250195 | D19: ='CO_Attainment for Unit Tests'!C18 -> BAGADE MANASI MUKUND
B20: 7 | C20: ='CO_Attainment for Unit Tests'!B19 -> 23510250196 | D20: ='CO_Attainment for Unit Tests'!C19 -> BARDE ARCHANA HANUMANT
B21: 8 | C21: ='CO_Attainment for Unit Tests'!B20 -> 23510250197 | D21: ='CO_Attainment for Unit Tests'!C20 -> BARMADE SHRADDHA SUDHAKAR
B22: 9 | C22: ='CO_Attainment for Unit Tests'!B21 -> 23510250198 | D22: ='CO_Attainment for Unit Tests'!C21 -> BEDKE ANKITA SHRIRAM
B23: 10 | C23: ='CO_Attainment for Unit Tests'!B22 -> 23510250199 | D23: ='CO_Attainment for Unit Tests'!C22 -> BHAD SHRAVANI UMAKANT
B24: 11 | C24: ='CO_Attainment for Unit Tests'!B23 -> 23510250200 | D24: ='CO_Attainment for Unit Tests'!C23 -> BHORE NIKITA SHANKAR
B25: 12 | C25: ='CO_Attainment for Unit Tests'!B24 -> 23510250201 | D25: ='CO_Attainment for Unit Tests'!C24 -> BHOSALE PRADNYA HARIDAS
... B96: 83 | C96: ='CO_Attainment for Unit Tests'!B95 -> 0 | D96: ='CO_Attainment for Unit Tests'!C95 -> 0
D97: #Set Competency target as Board's TSI | E97: =D98*E13/100 -> 32.879
D98: 46.97
D99: No. of students above set target | E99: =COUNTIF(E14:E96,">=" &E97) -> 0
B100: # Note : MSBTE TSI marks for the End Sem Board Exam is taken from MSBTE's result Gazette copy
A103: Benchmark of Attainment level against set target/ competency | E103: No of Students | G103: Level
A104: LEVEL | B104: 0.5 | C104: of Students got more than set target | E104: =COUNTA(D14:D96)-COUNTIFS(D14:D96,0) -> 63 | F104: =B104*$E$104 -> 31.5 | G104: 1
B105: 0.6 | C105: of Students got more than set target | F105: =B105*$E$104 -> 37.8 | G105: 2
B106: 0.7 | C106: of Students got more than set target | F106: =B106*$E$104 -> 44.1 | G106: 3
A109: CO-wise Attainment for End Sem Board Exam | C109: CO1 | D109: CO2 | E109: CO3 | F109: CO4 | G109: CO5 | H109: C06
A110: * Attainment Level | C110: =IF(E99>=$F106,3,IF(E99>=$F105,2,IF(E99>=$F104,1,0))) -> 0 | D110: =$C110 -> 0 | E110: =$C110 -> 0 | F110: =$C110 -> 0 | G110: =$C110 -> 0 | H110: =$C110 -> 0
A111: * Note - For End Sem Board Exam., same attainment level is considered for all Cos.

Sheet CO_attain_SLA_FA-PR_SA-PR
D1: Internal Evaluation of PA-Practical work, Micro-Project, PR-ESE
E2: Direct Assessment
C4: Course Name : | D4: ='CO_Attainment for Unit Tests'!C3 -> SEMINAR AND PROJECT INITIATION COURSE
C5: Course Code : | D5: ='CO_Attainment for Unit Tests'!C4 -> 315003
C6: Program/Semester : | D6: ='CO_Attainment for Unit Tests'!C5 -> 5th Sem Co5K K-Scheme
C7: Academic Year: | D7: ='CO_Attainment for Unit Tests'!C6 -> 2025-26
B9: Sr. No. | C9: Enrollment ID / Seat No | D9: Student Name | E9: SLA (Micro Project/Assignment Evaluation (max. marks ) | F9: FA-PR (Progressive Assessment -PA for Term work) (max marks ) | G9: SA-PR (Practical End Sem. Exam) ( max. marks)
E13: 25 | F13: 25 | G13: 25
B14: 1 | C14: ='CO_Attainment for Unit Tests'!B13 -> 2201180008 | D14: ='CO_Attainment for Unit Tests'!C13 -> DHANSHETTI PRIYA SANJAY | E14: 20 | F14: 20 | G14: 20
B15: 2 | C15: ='CO_Attainment for Unit Tests'!B14 -> 23510250191 | D15: ='CO_Attainment for Unit Tests'!C14 -> ADSUL SHASHWATI NITIN | E15: 24 | F15: 24 | G15: 23
B16: 3 | C16: ='CO_Attainment for Unit Tests'!B15 -> 23510250192 | D16: ='CO_Attainment for Unit Tests'!C15 -> AVISHKAR BABRUWAN BHISE | E16: 23 | F16: 23 | G16: 23
B17: 4 | C17: ='CO_Attainment for Unit Tests'!B16 -> 23510250193 | D17: ='CO_Attainment for Unit Tests'!C16 -> AWAD MAHESHWARI BHAU | E17: 24 | F17: 23 | G17: 22
B18: 5 | C18: ='CO_Attainment for Unit Tests'!B17 -> 23510250194 | D18: ='CO_Attainment for Unit Tests'!C17 -> BADVE SHARVANI DNYANESHWAR | E18: 24 | F18: 24 | G18: 24
B19: 6 | C19: ='CO_Attainment for Unit Tests'!B18 -> 23510250195 | D19: ='CO_Attainment for Unit Tests'!C18 -> BAGADE MANASI MUKUND | E19: 24 | F19: 24 | G19: 24
B20: 7 | C20: ='CO_Attainment for Unit Tests'!B19 -> 23510250196 | D20: ='CO_Attainment for Unit Tests'!C19 -> BARDE ARCHANA HANUMANT | E20: 23 | F20: 24 | G20: 22
B21: 8 | C21: ='CO_Attainment for Unit Tests'!B20 -> 23510250197 | D21: ='CO_Attainment for Unit Tests'!C20 -> BARMADE SHRADDHA SUDHAKAR | E21: 24 | F21: 24 | G21: 24
B22: 9 | C22: ='CO_Attainment for Unit Tests'!B21 -> 23510250198 | D22: ='CO_Attainment for Unit Tests'!C21 -> BEDKE ANKITA SHRIRAM | E22: 23 | F22: 23 | G22: 23
B23: 10 | C23: ='CO_Attainment for Unit Tests'!B22 -> 23510250199 | D23: ='CO_Attainment for Unit Tests'!C22 -> BHAD SHRAVANI UMAKANT | E23: 23 | F23: 23 | G23: 23
B24: 11 | C24: ='CO_Attainment for Unit Tests'!B23 -> 23510250200 | D24: ='CO_Attainment for Unit Tests'!C23 -> BHORE NIKITA SHANKAR | E24: 24 | F24: 23 | G24: 23
B25: 12 | C25: ='CO_Attainment for Unit Tests'!B24 -> 23510250201 | D25: ='CO_Attainment for Unit Tests'!C24 -> BHOSALE PRADNYA HARIDAS | E25: 23 | F25: 23 | G25: 22
... B76: 63 | C76: ='CO_Attainment for Unit Tests'!B75 -> 24510250266 | D76: ='CO_Attainment for Unit Tests'!C75 -> WAWALKAR ANJALI ANIL | E76: 21 | F76: 22 | G76: 22
B77: 64 | C77: ='CO_Attainment for Unit Tests'!B76 -> 0 | D77: ='CO_Attainment for Unit Tests'!C76 -> 0
B78: 65 | C78: ='CO_Attainment for Unit Tests'!B77 -> 0 | D78: ='CO_Attainment for Unit Tests'!C77 -> 0
B79: 66 | C79: ='CO_Attainment for Unit Tests'!B78 -> 0 | D79: ='CO_Attainment for Unit Tests'!C78 -> 0
B80: 67 | C80: ='CO_Attainment for Unit Tests'!B79 -> 0 | D80: ='CO_Attainment for Unit Tests'!C79 -> 0
B81: 68 | C81: ='CO_Attainment for Unit Tests'!B80 -> 0 | D81: ='CO_Attainment for Unit Tests'!C80 -> 0
B82: 69 | C82: ='CO_Attainment for Unit Tests'!B81 -> 0 | D82: ='CO_Attainment for Unit Tests'!C81 -> 0
B83: 70 | C83: ='CO_Attainment for Unit Tests'!B82 -> 0 | D83: ='CO_Attainment for Unit Tests'!C82 -> 0
B84: 71 | C84: ='CO_Attainment for Unit Tests'!B83 -> 0 | D84: ='CO_Attainment for Unit Tests'!C83 -> 0
B85: 72 | C85: ='CO_Attainment for Unit Tests'!B84 -> 0 | D85: ='CO_Attainment for Unit Tests'!C84 -> 0
B86: 73 | C86: ='CO_Attainment for Unit Tests'!B85 -> 0 | D86: ='CO_Attainment for Unit Tests'!C85 -> 0
B87: 74 | C87: ='CO_Attainment for Unit Tests'!B86 -> 0 | D87: ='CO_Attainment for Unit Tests'!C86 -> 0
B88: 75 | C88: ='CO_Attainment for Unit Tests'!B87 -> 0 | D88: ='CO_Attainment for Unit Tests'!C87 -> 0
... B96: 83 | C96: ='CO_Attainment for Unit Tests'!B95 -> 0 | D96: ='CO_Attainment for Unit Tests'!C95 -> 0
D97: Set Competency target as % marks for each criteria | E97: =ROUNDUP(D98*E13/100,1) -> 15 | F97: =ROUNDUP(D98*F13/100,1) -> 15 | G97: =ROUNDUP(D98*G13/100,1) -> 15
D98: 60
D99: No. of students above set target | E99: =COUNTIF(E14:E96,">=" &E97) -> 63 | F99: =COUNTIF(F14:F96,">=" &F97) -> 63 | G99: =COUNTIF(G14:G96,">=" &G97) -> 63
B103: Benchmark of Attainment level against set target/ competency for above criteria | E103: No of Students | G103: Level
B104: LEVEL | C104: 0.5 | D104: of Students got more than set target | E104: =COUNTA(D14:D96)-COUNTIFS(D14:D96,0) -> 63 | F104: =C104*$E104 -> 31.5 | G104: 1
C105: 0.6 | D105: of Students got more than set target | F105: =C105*$E104 -> 37.8 | G105: 2
...

Sheet CO_attainment for Indirect
C1: Indirect Assessment through Course end Survey
C4: Course Name : | D4: ='CO_attain_SLA_FA-PR_SA-PR'!D4 -> SEMINAR AND PROJECT INITIATION COURSE
C5: Course Code : | D5: ='CO_attain_SLA_FA-PR_SA-PR'!D5 -> 315003
C6: Program/Semester : | D6: ='CO_attain_SLA_FA-PR_SA-PR'!D6 -> 5th Sem Co5K K-Scheme
C7: Academic Year: | D7: ='CO_attain_SLA_FA-PR_SA-PR'!D7 -> 2025-26
B9: * Rating Scale : 5-Excellent, 4-Very good, 3- Good, 2-poor, 1-Very Poor
B10: Sr. No. | C10: Enrollment ID | D10: Student Name | E10: # Course Exit Survey of students ( * Rating Scale )
E14: 5
B15: 1 | C15: ='CO_attainment for FA-TH ESE'!C14 -> 2201180008 | D15: ='CO_attainment for FA-TH ESE'!D14 -> DHANSHETTI PRIYA SANJAY | E15: 0
C16: ='CO_attainment for FA-TH ESE'!#REF! -> #REF! | D16: ='CO_attainment for FA-TH ESE'!#REF! -> #REF!
B17: 2 | C17: ='CO_attainment for FA-TH ESE'!#REF! -> #REF! | D17: ='CO_attainment for FA-TH ESE'!#REF! -> #REF!
C18: ='CO_attainment for FA-TH ESE'!#REF! -> #REF! | D18: ='CO_attainment for FA-TH ESE'!#REF! -> #REF!
B19: 3 | C19: ='CO_attainment for FA-TH ESE'!#REF! -> #REF! | D19: ='CO_attainment for FA-TH ESE'!#REF! -> #REF!
C20: ='CO_attainment for FA-TH ESE'!#REF! -> #REF! | D20: ='CO_attainment for FA-TH ESE'!#REF! -> #REF!
C21: ='CO_attainment for FA-TH ESE'!#REF! -> #REF! | D21: ='CO_attainment for FA-TH ESE'!#REF! -> #REF!
B22: 4 | C22: ='CO_attainment for FA-TH ESE'!#REF! -> #REF! | D22: ='CO_attainment for FA-TH ESE'!#REF! -> #REF!
C23: ='CO_attainment for FA-TH ESE'!#REF! -> #REF! | D23: ='CO_attainment for FA-TH ESE'!#REF! -> #REF!
C24: ='CO_attainment for FA-TH ESE'!#REF! -> #REF! | D24: ='CO_attainment for FA-TH ESE'!#REF! -> #REF!
C25: ='CO_attainment for FA-TH ESE'!#REF! -> #REF! | D25: ='CO_attainment for FA-TH ESE'!#REF! -> #REF!
C26: ='CO_attainment for FA-TH ESE'!#REF! -> #REF! | D26: ='CO_attainment for FA-TH ESE'!#REF! -> #REF!
C27: ='CO_attainment for FA-TH ESE'!#REF! -> #REF! | D27: ='CO_attainment for FA-TH ESE'!#REF! -> #REF!
C28: ='CO_attainment for FA-TH ESE'!#REF! -> #REF! | D28: ='CO_attainment for FA-TH ESE'!#REF! -> #REF!
C29: ='CO_attainment for FA-TH ESE'!#REF! -> #REF! | D29: ='CO_attainment for FA-TH ESE'!#REF! -> #REF!
C30: ='CO_attainment for FA-TH ESE'!#REF! -> #REF! | D30: ='CO_attainment for FA-TH ESE'!#REF! -> #REF!
B31: 5 | C31: ='CO_attainment for FA-TH ESE'!#REF! -> #REF! | D31: ='CO_attainment for FA-TH ESE'!#REF! -> #REF!
C32: ='CO_attainment for FA-TH ESE'!#REF! -> #REF! | D32: ='CO_attainment for FA-TH ESE'!#REF! -> #REF!
C33: ='CO_attainment for FA-TH ESE'!#REF! -> #REF! | D33: ='CO_attainment for FA-TH ESE'!#REF! -> #REF!
C34: ='CO_attainment for FA-TH ESE'!#REF! -> #REF! | D34: ='CO_attainment for FA-TH ESE'!#REF! -> #REF!
C35: ='CO_attainment for FA-TH ESE'!#REF! -> #REF! | D35: ='CO_attainment for FA-TH ESE'!#REF! -> #REF!
C36: ='CO_attainment for FA-TH ESE'!#REF! -> #REF! | D36: ='CO_attainment for FA-TH ESE'!#REF! -> #REF!
C37: ='CO_attainment for FA-TH ESE'!#REF! -> #REF! | D37: ='CO_attainment for FA-TH ESE'!#REF! -> #REF!
B38: 6 | C38: ='CO_attainment for FA-TH ESE'!#REF! -> #REF! | D38: ='CO_attainment for FA-TH ESE'!#REF! -> #REF!
C39: ='CO_attainment for FA-TH ESE'!#REF! -> #REF! | D39: ='CO_attainment for FA-TH ESE'!#REF! -> #REF!
C40: ='CO_attainment for FA-TH ESE'!#REF! -> #REF! | D40: ='CO_attainment for FA-TH ESE'!#REF! -> #REF!
C41: ='CO_attainment for FA-TH ESE'!#REF! -> #REF! | D41: ='CO_attainment for FA-TH ESE'!#REF! -> #REF!
C42: ='CO_attainment for FA-TH ESE'!#REF! -> #REF! | D42: ='CO_attainment for FA-TH ESE'!#REF! -> #REF!
C43: ='CO_attainment for FA-TH ESE'!#REF! -> #REF! | D43: ='CO_attainment for FA-TH ESE'!#REF! -> #REF!
C44: ='CO_attainment for FA-TH ESE'!#REF! -> #REF! | D44: ='CO_attainment for FA-TH ESE'!#REF! -> #REF!
C45: ='CO_attainment for FA-TH ESE'!#REF! -> #REF! | D45: ='CO_attainment for FA-TH ESE'!#REF! -> #REF!
C46: ='CO_attainment for FA-TH ESE'!#REF! -> #REF! | D46: ='CO_attainment for FA-TH ESE'!#REF! -> #REF!
...

Sheet CO_PO Mapping Attainment 
F1: CO -PO Attainment
C4: Set Corelation of CO-PO Mapping
C5: Strength of corelation : 3 - high (Substantial), 2- medium, 1- low
B6: Sr. No. | C6: CO | E6: PO | O6: PSO
E7: PO1 | F7: PO2 | G7: PO3 | H7: PO4 | I7: PO5 | J7: PO6 | K7: PO7 | L7: PO8 | M7: PO9 | N7: PO10 | O7: PSO1 | P7: PSO2
E8: Basic Knowledge | F8: Discipline Knowledge | G8: Experiments and Practice | H8: Engineering tools | I8: The Engineer and Society | J8: Environment and Sustainability | K8: Ethics | L8: Individual and Team work | M8: Communication | N8: Life-long learning | O8: Modern software Usage | P8: Measurement of mechanical equipments
B9: 1 | C9: CO1 | D9: Apply the laws of thermodynamics to devices based on thermodynamics | E9: 3 | F9: 3 | G9: 2 | H9: 2 | I9: 2 | J9: 2 | K9: 2 | L9: 2 | M9: 2 | N9: 3 | O9: 3 | P9: 2
B10: 2 | C10: CO2 | D10: Use first law of thermodynamic for ideal gas in closed systems | E10: 3 | F10: 3 | G10: 1 | H10: 2 | I10: 2 | J10: 2 | K10: 2 | L10: 2 | M10: 2 | N10: 1 | O10: 2 | P10: 2
B11: 3 | C11: CO3 | D11: Use relevant steam boilers | E11: 3 | F11: 3 | G11: 2 | H11: 2 | I11: 2 | J11: 3 | K11: 2 | L11: 3 | M11: 2 | N11: 2 | O11: 2 | P11: 2
B12: 4 | C12: CO4 | D12: Use relevant steam nozzles and turbines | E12: 3 | F12: 3 | G12: 2 | H12: 3 | I12: 3 | J12: 2 | K12: 3 | L12: 2 | M12: 2 | N12: 3 | O12: 2 | P12: 2
B13: 5 | C13: CO5 | D13: Use relevant steam condensers | E13: 3 | F13: 3 | G13: 3 | H13: 3 | I13: 2 | J13: 2 | K13: 1 | L13: 3 | M13: 2 | N13: 2 | O13: 3 | P13: 3
B14: 6 | C14: CO6 | D14: Use suitable modes for heat transfer | E14: 3 | F14: 3 | G14: 2 | H14: 2 | I14: 1 | J14: 2 | K14: 1 | L14: 1 | M14: 2 | N14: 1 | O14: 2 | P14: 2
B15: Contribution to PO | E15: =ROUNDUP(AVERAGE(E9:E14),2) -> 3 | F15: =ROUNDUP(AVERAGE(F9:F14),2) -> 3 | G15: =ROUNDUP(AVERAGE(G9:G14),2) -> 2 | H15: =ROUNDUP(AVERAGE(H9:H14),2) -> 2.34 | I15: =ROUNDUP(AVERAGE(I9:I14),2) -> 2 | J15: =ROUNDUP(AVERAGE(J9:J14),2) -> 2.17 | K15: =ROUNDUP(AVERAGE(K9:K14),2) -> 1.84 | L15: =ROUNDUP(AVERAGE(L9:L14),2) -> 2.17 | ... P15: =ROUNDUP(AVERAGE(P9:P14),2) -> 2.17
B16: Course-PO attainment | E16: =ROUNDUP((E15*2.66)/3,2) -> 2.66 | F16: =ROUNDUP((F15*2.66)/3,2) -> 2.66 | G16: =ROUNDUP((G15*2.66)/3,2) -> 1.78 | H16: =ROUNDUP((H15*2.66)/3,2) -> 2.08 | I16: =ROUNDUP((I15*2.66)/3,2) -> 1.78 | J16: =ROUNDUP((J15*2.66)/3,2) -> 1.93 | K16: =ROUNDUP((K15*2.66)/3,2) -> 1.64 | L16: =ROUNDUP((L15*2.66)/3,2) -> 1.93 | ... P16: =ROUNDUP((P15*2.66)/3,2) -> 1.93
B17: % Course-PO attainment | E17: =ROUNDUP((E16/3)*100,2) -> 88.67 | F17: =ROUNDUP((F16/3)*100,2) -> 88.67 | G17: =ROUNDUP((G16/3)*100,2) -> 59.34 | H17: =ROUNDUP((H16/3)*100,2) -> 69.34 | I17: =ROUNDUP((I16/3)*100,2) -> 59.34 | J17: =ROUNDUP((J16/3)*100,2) -> 64.34 | K17: =ROUNDUP((K16/3)*100,2) -> 54.67 | L17: =ROUNDUP((L16/3)*100,2) -> 64.34 | ... P17: =ROUNDUP((P16/3)*100,2) -> 64.34

Sheet Overall CO attainment (2)
E1: Overall CO Attainment
C3: Course Name : | D3: ='CO_attainment for Indirect'!D4 -> SEMINAR AND PROJECT INITIATION COURSE
C4: Course Code : | D4: ='CO_attainment for Indirect'!D5 -> 315003
C5: Program/Semester : | D5: ='CO_attainment for Indirect'!D6 -> 5th Sem Co5K K-Scheme
C6: Academic Year: | D6: ='CO_attain_SLA_FA-PR_SA-PR'!D7 -> 2025-26
C8: Overall Course CO Attainment
C9: Final Direct Course Attainment Calculation | I9: Final Indirect Course Attainment Calculation
C10: COS | D10: Internal | H10: External
D11: Unit Tests | E11: PA_Term Work | F11: Micro- Project | G11: PR-ESE | H11: E.S.E Board | I11: Course Exit Survey
C12: CO1 | D12: ='CO_Attainment for Unit Tests'!D110 -> 0 | E12: ='CO_attain_SLA_FA-PR_SA-PR'!C111 -> 3 | F12: ='CO_attain_SLA_FA-PR_SA-PR'!C110 -> 3 | G12: ='CO_attain_SLA_FA-PR_SA-PR'!C112 -> 3 | H12: ='CO_attainment for FA-TH ESE'!C110 -> 0 | I12: ='CO_attainment for Indirect'!C91 -> 0
C13: CO2 | D13: ='CO_Attainment for Unit Tests'!E110 -> 0 | E13: =$E12 -> 3 | F13: =$F12 -> 3 | G13: =$G12 -> 3 | H13: =$H12 -> 0 | I13: =$I12 -> 0
C14: CO3 | D14: ='CO_Attainment for Unit Tests'!F110 -> 0 | E14: =$E13 -> 3 | F14: =$F13 -> 3 | G14: =$G13 -> 3 | H14: =$H13 -> 0 | I14: =$I13 -> 0
C15: CO4 | D15: ='CO_Attainment for Unit Tests'!G110 -> 0 | E15: =$E14 -> 3 | F15: =$F14 -> 3 | G15: =$G14 -> 3 | H15: =$H14 -> 0 | I15: =$I14 -> 0
C16: CO5 | D16: ='CO_Attainment for Unit Tests'!H110 -> 0 | E16: =$E15 -> 3 | F16: =$F15 -> 3 | G16: =$G15 -> 3 | H16: =$H15 -> 0 | I16: =$I15 -> 0
C17: CO6 | D17: ='CO_Attainment for Unit Tests'!I110 -> 0 | E17: =$E16 -> 3 | F17: =$F16 -> 3 | G17: =$G16 -> 3 | H17: =$H16 -> 0 | I17: =$I16 -> 0
C18: Average Attainment | D18: =ROUND(AVERAGE(D12:D17),2) -> 0 | E18: =ROUND(AVERAGE(E12:E17),2) -> 3 | F18: =ROUND(AVERAGE(F12:F17),2) -> 3 | G18: =ROUND(AVERAGE(G12:G17),2) -> 3 | H18: =ROUND(AVERAGE(H12:H17),2) -> 0 | I18: =ROUND(AVERAGE(I12:I17),2) -> 0
C19: Indiviual Weightage (%) | D19: 10 | E19: 10 | F19: 10 | G19: 10 | H19: 60 | I19: 100
C20: Direct Total Attainment | D20: =D18*D19/100 -> 0 | E20: =E18*E19/100 -> 0.3 | F20: =F18*F19/100 -> 0.3 | G20: =G18*G19/100 -> 0.3 | H20: =H18*H19/100 -> 0 | I20: =I18*I19/100 -> 0
C21: Total Direct Course Attainment | H21: =SUM(D20:H20) -> 0.9 | I21: Total Indirect Course Attainment | J21: =I20 -> 0
C22: Overall Weightage | H22: 0.8 | I22: Weightage | J22: 0.2
C23: Final Direct Course Attainment | H23: =0.8*H21 -> 0.72 | I23: Final Indirect Course Attainment | J23: =0.2*J21 -> 0
C24: Overall Course CO Attainment (B) | I24: =ROUNDUP(H23+J23,2) -> 0.72
G30: Template sheet is Prepared by Prof. A.B.Bhure
G31: L.M.E., P.L.G.P. Latur

Sheet Overall CO attainment
E1: Overall CO Attainment
C3: Course Name : | D3: ='CO_attainment for Indirect'!D4 -> SEMINAR AND PROJECT INITIATION COURSE
C4: Course Code : | D4: ='CO_attainment for Indirect'!D5 -> 315003
C5: Program/Semester : | D5: ='CO_attainment for Indirect'!D6 -> 5th Sem Co5K K-Scheme
C6: Academic Year: | D6: ='CO_attain_SLA_FA-PR_SA-PR'!D7 -> 2025-26
C8: DIRECT CO ASSESSMENT TOOL/COURSE EVALUATION PLAN | E8: TH-PA | H8: FA-PR | I8: SA-PR | J8: TH-ESE | K8: TOTAL
E9: U.Test I | F9: U. Test II | G9: SLA | H9: PA_Term Work | I9: Practical Exam | J9: E.S.E Board
C10: MAX MARKS AS PER TEACHING SCHEME | E10: 0 | G10: 25 | H10: 25 | I10: 25 | J10: 0 | K10: =SUM(E10:J10) -> 75
C11: INDIVIDUAL WEIGHTAGE (%) | E11: =(E10/$K10)*100 -> 0 | G11: =(G10/$K10)*100 -> 33.333333 | H11: =(H10/$K10)*100 -> 33.333333 | I11: =(I10/$K10)*100 -> 33.333333 | J11: =(J10/$K10)*100 -> 0 | K11: =SUM(E11:J11) -> 100
C15: Overall Course CO Attainment
C16: Final Direct Course Attainment Calculation
C17: COS | E17: Internal | H17: External
D18: Unit Tests | E18: PA_Term Work | F18: Micro- Project | G18: PR-ESE | H18: E.S.E Board
C19: CO1 | D19: ='CO_Attainment for Unit Tests'!D110 -> 0 | E19: ='CO_attain_SLA_FA-PR_SA-PR'!C111 -> 3 | F19: ='CO_attain_SLA_FA-PR_SA-PR'!C110 -> 3 | G19: ='CO_attain_SLA_FA-PR_SA-PR'!C112 -> 3 | H19: ='CO_attainment for FA-TH ESE'!C110 -> 0
C20: CO2 | D20: ='CO_Attainment for Unit Tests'!E110 -> 0 | E20: =$E19 -> 3 | F20: =$F19 -> 3 | G20: =$G19 -> 3 | H20: =$H19 -> 0
C21: CO3 | D21: ='CO_Attainment for Unit Tests'!F110 -> 0 | E21: =$E20 -> 3 | F21: =$F20 -> 3 | G21: =$G20 -> 3 | H21: =$H20 -> 0
C22: CO4 | D22: ='CO_Attainment for Unit Tests'!G110 -> 0 | E22: =$E21 -> 3 | F22: =$F21 -> 3 | G22: =$G21 -> 3 | H22: =$H21 -> 0
C23: CO5 | D23: ='CO_Attainment for Unit Tests'!H110 -> 0 | E23: =$E22 -> 3 | F23: =$F22 -> 3 | G23: =$G22 -> 3 | H23: =$H22 -> 0
C24: CO6 | D24: ='CO_Attainment for Unit Tests'!I110 -> 0 | E24: =$E23 -> 3 | F24: =$F23 -> 3 | G24: =$G23 -> 3 | H24: =$H23 -> 0
C25: Average Attainment | D25: =ROUND(AVERAGE(D19:D24),2) -> 0 | E25: =ROUND(AVERAGE(E19:E24),2) -> 3 | F25: =ROUND(AVERAGE(F19:F24),2) -> 3 | G25: =ROUND(AVERAGE(G19:G24),2) -> 3 | H25: =ROUND(AVERAGE(H19:H24),2) -> 0
C26: Indiviual Weightage (%) | D26: =E11 -> 0 | E26: =H11 -> 33.333333 | F26: =G11 -> 33.333333 | G26: =I11 -> 33.333333 | H26: =J11 -> 0
C27: Direct Total Attainment | D27: =D25*D26/100 -> 0 | E27: =E25*E26/100 -> 1 | F27: =F25*F26/100 -> 1 | G27: =G25*G26/100 -> 1 | H27: =H25*H26/100 -> 0
C28: Total Direct Course Attainment | H28: =SUM(D27:H27) -> 3
C29: Overall Weightage | H29: 1
C30: Final Direct Course Attainment | H30: =H29*H28 -> 3
C31: Overall Course CO Attainment (B) | I31: =H30+J30 -> 3
H34: Name of Faculty & Signature
H35: GOVERNMENT POLYTECHNIC DHARASHIV

Sheet CO_PO Mapping Attainment_PO7
E1: CO -PO Actual Attainment
C2: Course Name : | D2: ='Overall CO attainment'!D3 -> SEMINAR AND PROJECT INITIATION COURSE
C3: Course Code : | D3: ='Overall CO attainment'!D4 -> 315003
C4: Program/Scheme-MSBTE Inst.code : | D4: ='Overall CO attainment'!D5 -> 5th Sem Co5K K-Scheme
C5: Academic Year: | D5: ='Overall CO attainment'!D6 -> 2025-26
B8: Strength of correlation : 3 - high (Substantial), 2- medium(moderate), 1- low, No relation : '-'
B9: Sr. No. | C9: CO | E9: PO | L9: PSO
E10: PO1 | F10: PO2 | G10: PO3 | H10: PO4 | I10: PO5 | J10: PO6 | K10: PO7 | L10: PSO1 | M10: PSO2
E11: Basic Knowledge & Discipline Knowledge | F11: Problem analysis | G11: Design/developmet of solutions | H11: Engineering tools, Experimentation and Testing | I11: Engineering Practices for society, sustainability , Environment, Ethics | J11: Project Management | K11: Life Long learning | L11: Computer Software and Hardware Usage | M11: Computer Engineering Maintenance
B12: ='PO Set Target attain level'!B19 -> 1 | C12: ='PO Set Target attain level'!C19 -> CO1 | D12: ='PO Set Target attain level'!D19 -> Identify topics of seminar presenting to the large gathering at the institute/conference. | E12: ='PO Set Target attain level'!E19 -> 3 | F12: ='PO Set Target attain level'!F19 -> 1 | G12: ='PO Set Target attain level'!G19 -> - | H12: ='PO Set Target attain level'!H19 -> - | I12: ='PO Set Target attain level'!I19 -> 2 | ... M12: ='PO Set Target attain level'!M19 -> -
B13: ='PO Set Target attain level'!B20 -> 2 | C13: ='PO Set Target attain level'!C20 -> CO2 | D13: ='PO Set Target attain level'!D20 -> Collect relevant and updated research-based data and information to prepare a paper of seminar presentation. | E13: ='PO Set Target attain level'!E20 -> 2 | F13: ='PO Set Target attain level'!F20 -> - | G13: ='PO Set Target attain level'!G20 -> 2 | H13: ='PO Set Target attain level'!H20 -> - | I13: ='PO Set Target attain level'!I20 -> 2 | ... M13: ='PO Set Target attain level'!M20 -> 1
B14: ='PO Set Target attain level'!B21 -> 3 | C14: ='PO Set Target attain level'!C21 -> CO3 | D14: ='PO Set Target attain level'!D21 -> Apply presentation skills. | E14: ='PO Set Target attain level'!E21 -> 3 | F14: ='PO Set Target attain level'!F21 -> 1 | G14: ='PO Set Target attain level'!G21 -> 1 | H14: ='PO Set Target attain level'!H21 -> 2 | I14: ='PO Set Target attain level'!I21 -> 1 | ... M14: ='PO Set Target attain level'!M21 -> -
B15: ='PO Set Target attain level'!B22 -> 4 | C15: ='PO Set Target attain level'!C22 -> CO4 | D15: ='PO Set Target attain level'!D22 -> Create conducive environment for learning and discussion through seminar presentation. | E15: ='PO Set Target attain level'!E22 -> 2 | F15: ='PO Set Target attain level'!F22 -> - | G15: ='PO Set Target attain level'!G22 -> - | H15: ='PO Set Target attain level'!H22 -> 2 | I15: ='PO Set Target attain level'!I22 -> 1 | ... M15: ='PO Set Target attain level'!M22 -> -
B16: ='PO Set Target attain level'!B23 -> 5 | C16: ='PO Set Target attain level'!C23 -> CO5 | D16: ='PO Set Target attain level'!D23 -> Identify a problem statement and establish the action plan for the successful completion of the project. | E16: 2 | F16: ='PO Set Target attain level'!F23 -> 3 | G16: ='PO Set Target attain level'!G23 -> 3 | H16: ='PO Set Target attain level'!H23 -> 2 | I16: ='PO Set Target attain level'!I23 -> 2 | J16: ='PO Set Target attain level'!J23 -> 3 | K16: ='PO Set Target attain level'!K23 -> 3 | L16: ='PO Set Target attain level'!L23 -> 2 | M16: ='PO Set Target attain level'!M23 -> 3
B17: Average Contribution of each CO to each PO (A) | E17: =IFERROR(AVERAGE(E12:E16),0) -> 2.4 | F17: =IFERROR(AVERAGE(F12:F16),0) -> 1.6666667 | G17: =IFERROR(AVERAGE(G12:G16),0) -> 2 | H17: =IFERROR(AVERAGE(H12:H16),0) -> 2 | I17: =IFERROR(AVERAGE(I12:I16),0) -> 1.6 | J17: =IFERROR(AVERAGE(J12:J16),0) -> 2 | K17: =IFERROR(AVERAGE(K12:K16),0) -> 3 | L17: =IFERROR(AVERAGE(L12:L16),2) -> 1.5 | M17: =IFERROR(AVERAGE(M12:M16),2) -> 2
B18: Course CO-PO ACTUAL ATTAINMENT LEVEL= ((AxB)/3) | E18: =E17*'Overall CO attainment'!I31/3 -> 2.4 | F18: =F17*'Overall CO attainment'!I31/3 -> 1.6666667 | G18: =G17*'Overall CO attainment'!I31/3 -> 2 | H18: =H17*'Overall CO attainment'!I31/3 -> 2 | I18: =I17*'Overall CO attainment'!I31/3 -> 1.6 | J18: =J17*'Overall CO attainment'!I31/3 -> 2 | K18: =K17*'Overall CO attainment'!I31/3 -> 3 | L18: =L17 -> 1.5 | M18: =M17 -> 2
B19: % Course-PO attainment | E19: =ROUNDUP((E18/3)*100,2) -> 80 | F19: =ROUNDUP((F18/3)*100,2) -> 55.56 | G19: =ROUNDUP((G18/3)*100,2) -> 66.67 | H19: =ROUNDUP((H18/3)*100,2) -> 66.67 | I19: =ROUNDUP((I18/3)*100,2) -> 53.34 | J19: =ROUNDUP((J18/3)*100,2) -> 66.67 | K19: =ROUNDUP((K18/3)*100,2) -> 100 | L19: =ROUNDUP((L18/3)*100,2) -> 50 | M19: =ROUNDUP((M18/3)*100,2) -> 66.67
J22: Name of Faculty & Signature
J23: GOVERNMENT POLYTECHNIC DHARASHIV

Sheet Justification for Mapping
A4: Justification for Mapping
A6: CO1 -> PSO1 (1): Identifying relevant technical topics requires foundational knowledge of hardware/software trends.
A8: CO2 -> PSO1 (2) & PSO2 (1): Researching technical content heavily relies on software/hardware architectural knowledge, with a secondary need to understand system requirements for data processing.
A10: CO3 -> PSO1 (1): Effective communication of technical concepts is a key skill for software/hardware engineers.
A12: CO5 -> PSO1 (2) & PSO2 (3): This is the strongest link. Successful project initiation—including planning, resource allocation, and problem statement formulation—is directly dependent on the ability to architect, maintain, and optimize computing resources
