Workbook

Sheet PO Set Target attain level
D1: PO-CO Mapping (Targetted Level) - Course Articulation Matrix
C3: Course Name : | D3: Data Structures Using _C
C4: Course Code : | D4: 22317
C5: Program/Scheme-MSBTE Inst.code : | D5: 3rd SEM(CO3I SCHEME)
C6: Academic Year : | D6: 2023-24
B7: Course Outcomes :
C8: CO1 | D8: Perform basic operations on arrays
C9: CO2 | D9: Apply different searching and sorting techniques.
C10: CO3 | D10: Implement basic operations on stack and queue using array representation
C11: CO4 | D11: Implement basic operations on Linked List
C12: CO5 | D12: Implement program to create and traverse tree to solve problems
B15: Set Correlation of CO-PO Mapping
B16: Strength of correlation : 3 - high (Substantial), 2- medium (moderate) , 1- low, No relation : '-'
B17: Sr. No. | C17: CO | E17: PO | L17: PSO
E18: PO1 | F18: PO2 | G18: PO3 | H18: PO4 | I18: PO5 | J18: PO6 | K18: PO7 | L18: PSO1 | M18: PSO2
E19: Basic Knowledge & Discipline Knowledge | F19: Problem analysis | G19: Design/developmet of solutions | H19: Engineering tools, Experimentation and Testing | I19: Engineering Practices for society, sustainability , Environment, Ethics | J19: Project Management | K19: Life Long learning | L19: Computer Software and Hardware Usage | M19: Computer Engineering Maintenance
B20: 1 | C20: =C8 -> CO1 | D20: =D8 -> Perform basic operations on arrays
B21: 2 | C21: =C9 -> CO2 | D21: =D9 -> Apply different searching and sorting techniques.
B22: 3 | C22: =C10 -> CO3 | D22: =D10 -> Implement basic operations on stack and queue using array representation
B23: 4 | C23: =C11 -> CO4 | D23: =D11 -> Implement basic operations on Linked List
B24: 5 | C24: =C12 -> CO5 | D24: =D12 -> Implement program to create and traverse tree to solve problems
D25: =D13
B26: Average | E26: =IFERROR(AVERAGE(E20:E24),2) -> 2 | F26: =IFERROR(AVERAGE(F20:F24),2) -> 2 | G26: =IFERROR(AVERAGE(G20:G24),2) -> 2 | H26: =IFERROR(AVERAGE(H20:H24),2) -> 2 | I26: =IFERROR(AVERAGE(I20:I24),2) -> 2 | J26: =IFERROR(AVERAGE(J20:J24),2) -> 2 | K26: =IFERROR(AVERAGE(K20:K24),2) -> 2 | L26: =IFERROR(AVERAGE(L20:L24),2) -> 2 | M26: =IFERROR(AVERAGE(M20:M24),2) -> 2
B27: Targeted Attainment Level | E27: =E26 -> 2 | F27: =F26 -> 2 | G27: =G26 -> 2 | H27: =H26 -> 2 | I27: =I26 -> 2 | J27: =J26 -> 2 | K27: =K26 -> 2 | L27: =L26 -> 2 | M27: =M26 -> 2
D30: HOD COMPUTER | I30: Name of Faculty & Signature
C31: GOVERNMENT POLYTECHNIC DHARASHIV | I31: GOVERNMENT POLYTECHNIC DHARASHIV
B35: Note : | D35: Fill only this colour cells for all worksheets
D36: This cells are autofilled fields . Do not overwrite this cells for all worksheets

Sheet CO_Attainment for Unit Tests
A1: Evaluation of Answersheets for FA-TH(Unit Test)
A2: Internal Assessment ( Direct Mode)
B3: Course Name : | C3: ='PO Set Target attain level'!D3 -> Data Structures Using _C
B4: Course Code : | C4: ='PO Set Target attain level'!D4 -> 22317
B5: Program/Semester : | C5: ='PO Set Target attain level'!D5 -> 3rd SEM(CO3I SCHEME)
B6: Academic Year | C6: ='PO Set Target attain level'!D6 -> 2023-24
A8: Sr. No. | B8: Enrollment ID / Seat No | C8: Student Name | D8: CO1 max. Marks | E8: CO2 max. Marks | F8: CO3 max. Marks | G8: CO4 max. Marks | H8: CO5 max. Marks | I8: CO6 max. Marks | J8: U. TEST I | K8: U. TEST II
J9: Total Max. Marks(with Extra)
J12: =D12+E12 -> 0 | K12: =G12+H12+I12+F12 -> 0
A13: 1 | B13: 2201180002 | C13: GARAD ANJALI NITIN | J13: =D13+E13 -> 0 | K13: =G13+H13+I13+F13 -> 0
A14: 2 | B14: 2201180003 | C14: WALANDE GAURI DAYANAND | J14: =D14+E14 -> 0 | K14: =G14+H14+I14+F14 -> 0
A15: 3 | B15: 2201180004 | C15: ZUNJURE SARTHAK BALAJI | J15: =D15+E15 -> 0 | K15: =G15+H15+I15+F15 -> 0
A16: 4 | B16: 2201180005 | C16: BHANDE GAYATRI DAMODAR | J16: =D16+E16 -> 0 | K16: =G16+H16+I16+F16 -> 0
A17: 5 | B17: 2201180006 | C17: MUNDHE GAYATRI PARMESHWAR | J17: =D17+E17 -> 0 | K17: =G17+H17+I17+F17 -> 0
A18: 6 | B18: 2201180009 | C18: YADAV RADHA SAMADHAN | J18: =D18+E18 -> 0 | K18: =G18+H18+I18+F18 -> 0
A19: 7 | B19: 2201180010 | C19: DESHMANE MANSI SIDDHESHWAR | J19: =D19+E19 -> 0 | K19: =G19+H19+I19+F19 -> 0
A20: 8 | B20: 2201180011 | C20: GAWALGADADE POOJA ARVIND | J20: =D20+E20 -> 0 | K20: =G20+H20+I20+F20 -> 0
A21: 9 | B21: 2201180014 | C21: JAIN TANISHA SHAILESH | J21: =D21+E21 -> 0 | K21: =G21+H21+I21+F21 -> 0 | S21: 9 | T21: 2201180012 | U21: KAMBLE PRANAV UDDHAV | V21: 2 | W21: 1 | X21: 4 | Y21: 4 | Z21: 4 | AB21: =V21+W21 -> 3 | AC21: =Y21+Z21+AA21+X21 -> 12
A22: 10 | B22: 2201180050 | C22: MAINDARGE SIDDHI PRASAD | J22: =D22+E22 -> 0 | K22: =G22+H22+I22+F22 -> 0 | S22: 34 | T22: 2201180236 | U22: CHAVAN POOJA BALASAHEB | V22: 5 | W22: 10 | X22: 1 | Y22: 1 | Z22: 5 | AB22: =V22+W22 -> 15 | AC22: =Y22+Z22+AA22+X22 -> 7
A23: 11 | B23: 2201180051 | C23: BHOSALE VAISHNAVI DAYANAND | J23: =D23+E23 -> 0 | K23: =G23+H23+I23+F23 -> 0 | S23: 37 | T23: 2201180240 | U23: NAHANE VIVEK KAKASAHEB | V23: 2 | W23: 7 | X23: 7 | Y23: 8 | Z23: 6 | AB23: =V23+W23 -> 9 | AC23: =Y23+Z23+AA23+X23 -> 21
A24: 12 | B24: 2201180052 | C24: ATTAR SANIYA VAJIR | J24: =D24+E24 -> 0 | K24: =G24+H24+I24+F24 -> 0 | S24: 45 | T24: 2201180402 | U24: SOMVANSHI MADHAV SHRIRANG | V24: 6 | W24: 7 | AB24: =V24+W24 -> 13 | AC24: =Y24+Z24+AA24+X24 -> 0
A25: 13 | B25: 2201180053 | C25: NALWADE SNEHA NETAJI | J25: =D25+E25 -> 0 | K25: =G25+H25+I25+F25 -> 0 | S25: 46 | T25: 2201180403 | U25: SWAMI KEDAR RACHAPPA | V25: 6 | W25: 2 | AB25: =V25+W25 -> 8 | AC25: =Y25+Z25+AA25+X25 -> 0
A26: 14 | B26: 2201180055 | C26: AADHE PANKAJ RAM | J26: =D26+E26 -> 0 | K26: =G26+H26+I26+F26 -> 0 | S26: 52 | T26: 2201180409 | U26: KALE ADITYA SURESH | AB26: =V26+W26 -> 0 | AC26: =Y26+Z26+AA26+X26 -> 0
A27: 15 | B27: 2201180056 | C27: BUDGE VISHAKHA VENKAT | J27: =D27+E27 -> 0 | K27: =G27+H27+I27+F27 -> 0
A28: 16 | B28: 2201180058 | C28: PAWAR PRATIKSHA VITTHAL | J28: =D28+E28 -> 0 | K28: =G28+H28+I28+F28 -> 0
A29: 17 | B29: 2201180059 | C29: WAGHMARE RAU HANMANT | J29: =D29+E29 -> 0 | K29: =G29+H29+I29+F29 -> 0
A30: 18 | B30: 2201180060 | C30: MAHAJAN SHRUTI DILIP | J30: =D30+E30 -> 0 | K30: =G30+H30+I30+F30 -> 0
A31: 19 | B31: 2201180061 | C31: CHANDANE GAYATRI PRASHANT | J31: =D31+E31 -> 0 | K31: =G31+H31+I31+F31 -> 0
A32: 20 | B32: 2201180062 | C32: JOSHI SHRAVANI SHRIKANT | J32: =D32+E32 -> 0 | K32: =G32+H32+I32+F32 -> 0
A33: 21 | B33: 2201180063 | C33: MANE ANUSHKA BALASAHEB | J33: =D33+E33 -> 0 | K33: =G33+H33+I33+F33 -> 0
A34: 22 | B34: 2201180064 | C34: GADEKAR MAHESH BALAJI | J34: =D34+E34 -> 0 | K34: =G34+H34+I34+F34 -> 0
A35: 23 | B35: 2201180065 | C35: DESHMUKH SWANANDI UDAYRAO | J35: =D35+E35 -> 0 | K35: =G35+H35+I35+F35 -> 0
A36: 24 | B36: 2201180148 | C36: LAGDIVE SHIVAM NITIN | J36: =D36+E36 -> 0 | K36: =G36+H36+I36+F36 -> 0
A37: 25 | B37: 2201180227 | C37: SARPHALE POOJA SADASHIV | J37: =D37+E37 -> 0 | K37: =G37+H37+I37+F37 -> 0
A38: 26 | B38: 2201180228 | C38: WAGHMARE ABHISHEK SOMNATH | J38: =D38+E38 -> 0 | K38: =G38+H38+I38+F38 -> 0
... A68: 56 | B68: 2201180419 | C68: MULE SNEHA SANJIVAN | J68: =D68+E68 -> 0 | K68: =G68+H68+I68+F68 -> 0
A69: 57 | B69: 23510250259 | C69: BANSODE VINAYAK BABRUWAN
A70: 58 | B70: 23510250260 | C70: ISHWARI ASHOK HAWALE
A71: 59 | B71: 23510250261 | C71: JADHAV SANJYOT SHYAM | J71: =D71+E71 -> 0 | K71: =G71+H71+I71+F71 -> 0
A72: 60 | B72: 23510250262 | C72: KANLOD SHUBHAM GANPAT | J72: =D72+E72 -> 0 | K72: =G72+H72+I72+F72 -> 0
...

Sheet CO_attainment for FA-TH ESE
B1: External Evaluation of End Semester Board Examination
D2: Direct Assessment
C4: Course Name : | D4: ='CO_Attainment for Unit Tests'!C3 -> Data Structures Using _C
C5: Course Code : | D5: ='CO_Attainment for Unit Tests'!C4 -> 22317
C6: Program/Semester : | D6: ='CO_Attainment for Unit Tests'!C5 -> 3rd SEM(CO3I SCHEME)
C7: Academic Year : | D7: ='CO_Attainment for Unit Tests'!C6 -> 2023-24
B9: Sr. No. | C9: Enrollment ID / Seat No | D9: Student Name | E9: TH-ESE (End Sem Board Exam.) Max. Marks
E13: 70
B14: 1 | C14: ='CO_Attainment for Unit Tests'!B13 -> 2201180002 | D14: ='CO_Attainment for Unit Tests'!C13 -> GARAD ANJALI NITIN | E14: 29
B15: 2 | C15: ='CO_Attainment for Unit Tests'!B14 -> 2201180003 | D15: ='CO_Attainment for Unit Tests'!C14 -> WALANDE GAURI DAYANAND | E15: 47
B16: 3 | C16: ='CO_Attainment for Unit Tests'!B15 -> 2201180004 | D16: ='CO_Attainment for Unit Tests'!C15 -> ZUNJURE SARTHAK BALAJI | E16: 54
B17: 4 | C17: ='CO_Attainment for Unit Tests'!B16 -> 2201180005 | D17: ='CO_Attainment for Unit Tests'!C16 -> BHANDE GAYATRI DAMODAR | E17: 63
B18: 5 | C18: ='CO_Attainment for Unit Tests'!B17 -> 2201180006 | D18: ='CO_Attainment for Unit Tests'!C17 -> MUNDHE GAYATRI PARMESHWAR | E18: 51
B19: 6 | C19: ='CO_Attainment for Unit Tests'!B18 -> 2201180009 | D19: ='CO_Attainment for Unit Tests'!C18 -> YADAV RADHA SAMADHAN | E19: 40
B20: 7 | C20: ='CO_Attainment for Unit Tests'!B19 -> 2201180010 | D20: ='CO_Attainment for Unit Tests'!C19 -> DESHMANE MANSI SIDDHESHWAR | E20: 53
B21: 8 | C21: ='CO_Attainment for Unit Tests'!B20 -> 2201180011 | D21: ='CO_Attainment for Unit Tests'!C20 -> GAWALGADADE POOJA ARVIND | E21: 30
B22: 9 | C22: ='CO_Attainment for Unit Tests'!B21 -> 2201180014 | D22: ='CO_Attainment for Unit Tests'!C21 -> JAIN TANISHA SHAILESH | E22: 46
B23: 10 | C23: ='CO_Attainment for Unit Tests'!B22 -> 2201180050 | D23: ='CO_Attainment for Unit Tests'!C22 -> MAINDARGE SIDDHI PRASAD | E23: 48
B24: 11 | C24: ='CO_Attainment for Unit Tests'!B23 -> 2201180051 | D24: ='CO_Attainment for Unit Tests'!C23 -> BHOSALE VAISHNAVI DAYANAND | E24: 51
B25: 12 | C25: ='CO_Attainment for Unit Tests'!B24 -> 2201180052 | D25: ='CO_Attainment for Unit Tests'!C24 -> ATTAR SANIYA VAJIR | E25: 66
... B69: 56 | C69: ='CO_Attainment for Unit Tests'!B68 -> 2201180419 | D69: ='CO_Attainment for Unit Tests'!C68 -> MULE SNEHA SANJIVAN | E69: 56
B70: 57 | C70: ='CO_Attainment for Unit Tests'!B69 -> 23510250259 | D70: ='CO_Attainment for Unit Tests'!C69 -> BANSODE VINAYAK BABRUWAN
B71: 58 | C71: ='CO_Attainment for Unit Tests'!B70 -> 23510250260 | D71: ='CO_Attainment for Unit Tests'!C70 -> ISHWARI ASHOK HAWALE
B72: 59 | C72: ='CO_Attainment for Unit Tests'!B71 -> 23510250261 | D72: ='CO_Attainment for Unit Tests'!C71 -> JADHAV SANJYOT SHYAM | E72: 49
B73: 60 | C73: ='CO_Attainment for Unit Tests'!B72 -> 23510250262 | D73: ='CO_Attainment for Unit Tests'!C72 -> KANLOD SHUBHAM GANPAT | E73: 54
B74: 61 | C74: ='CO_Attainment for Unit Tests'!B73 -> 23510250263 | D74: ='CO_Attainment for Unit Tests'!C73 -> PHULARI VISHVJEET UMESH | E74: 42
B75: 62 | C75: ='CO_Attainment for Unit Tests'!B74 -> 23510250264 | D75: ='CO_Attainment for Unit Tests'!C74 -> VHOTTE SHRUTIKA VAIJNATH
B76: 63 | C76: ='CO_Attainment for Unit Tests'!B75 | D76: ='CO_Attainment for Unit Tests'!C75
B77: 64 | C77: ='CO_Attainment for Unit Tests'!B76 | D77: ='CO_Attainment for Unit Tests'!C76
B78: 65 | C78: ='CO_Attainment for Unit Tests'!B77 | D78: ='CO_Attainment for Unit Tests'!C77
B79: 66 | C79: ='CO_Attainment for Unit Tests'!B78 | D79: ='CO_Attainment for Unit Tests'!C78
B80: 67 | C80: ='CO_Attainment for Unit Tests'!B78 | D80: ='CO_Attainment for Unit Tests'!C75
B81: 68 | C81: ='CO_Attainment for Unit Tests'!B79 | D81: ='CO_Attainment for Unit Tests'!C76
B82: 69 | C82: ='CO_Attainment for Unit Tests'!B80 | D82: ='CO_Attainment for Unit Tests'!C77
B83: 70 | C83: ='CO_Attainment for Unit Tests'!B81 | D83: ='CO_Attainment for Unit Tests'!C78
B84: 71 | C84: ='CO_Attainment for Unit Tests'!B82 | D84: ='CO_Attainment for Unit Tests'!C82
B85: 72 | C85: ='CO_Attainment for Unit Tests'!B83 | D85: ='CO_Attainment for Unit Tests'!C83
B86: 73 | C86: ='CO_Attainment for Unit Tests'!B84 | D86: ='CO_Attainment for Unit Tests'!C84
B87: 74 | C87: ='CO_Attainment for Unit Tests'!B85 | D87: ='CO_Attainment for Unit Tests'!C85
B88: 75 | C88: ='CO_Attainment for Unit Tests'!B86 | D88: ='CO_Attainment for Unit Tests'!C86
...

Sheet CO_attain_SLA_FA-PR_SA-PR
D1: Internal Evaluation of PA-Practical work, Micro-Project, PR-ESE
E2: Direct Assessment
C4: Course Name : | D4: ='CO_Attainment for Unit Tests'!C3 -> Data Structures Using _C
C5: Course Code : | D5: ='CO_Attainment for Unit Tests'!C4 -> 22317
C6: Program/Semester : | D6: ='CO_Attainment for Unit Tests'!C5 -> 3rd SEM(CO3I SCHEME)
C7: Academic Year: | D7: ='CO_Attainment for Unit Tests'!C6 -> 2023-24
B9: Sr. No. | C9: Enrollment ID / Seat No | D9: Student Name | E9: (Micro Project/Assignment Evaluation (max. marks ) | F9: PR-PA | G9: PR-ESE
E13: 10 | F13: 25 | G13: 25
B14: 1 | C14: ='CO_Attainment for Unit Tests'!B13 -> 2201180002 | D14: ='CO_Attainment for Unit Tests'!C13 -> GARAD ANJALI NITIN | F14: 13 | G14: 19
B15: 2 | C15: ='CO_Attainment for Unit Tests'!B14 -> 2201180003 | D15: ='CO_Attainment for Unit Tests'!C14 -> WALANDE GAURI DAYANAND | F15: 22 | G15: 21
B16: 3 | C16: ='CO_Attainment for Unit Tests'!B15 -> 2201180004 | D16: ='CO_Attainment for Unit Tests'!C15 -> ZUNJURE SARTHAK BALAJI | F16: 22 | G16: 22
B17: 4 | C17: ='CO_Attainment for Unit Tests'!B16 -> 2201180005 | D17: ='CO_Attainment for Unit Tests'!C16 -> BHANDE GAYATRI DAMODAR | F17: 24 | G17: 24
B18: 5 | C18: ='CO_Attainment for Unit Tests'!B17 -> 2201180006 | D18: ='CO_Attainment for Unit Tests'!C17 -> MUNDHE GAYATRI PARMESHWAR | F18: 24 | G18: 24
B19: 6 | C19: ='CO_Attainment for Unit Tests'!B18 -> 2201180009 | D19: ='CO_Attainment for Unit Tests'!C18 -> YADAV RADHA SAMADHAN | F19: 22 | G19: 21
B20: 7 | C20: ='CO_Attainment for Unit Tests'!B19 -> 2201180010 | D20: ='CO_Attainment for Unit Tests'!C19 -> DESHMANE MANSI SIDDHESHWAR | F20: 23 | G20: 21
B21: 8 | C21: ='CO_Attainment for Unit Tests'!B20 -> 2201180011 | D21: ='CO_Attainment for Unit Tests'!C20 -> GAWALGADADE POOJA ARVIND | F21: 22 | G21: 20
B22: 9 | C22: ='CO_Attainment for Unit Tests'!B21 -> 2201180014 | D22: ='CO_Attainment for Unit Tests'!C21 -> JAIN TANISHA SHAILESH | F22: 19 | G22: 21
B23: 10 | C23: ='CO_Attainment for Unit Tests'!B22 -> 2201180050 | D23: ='CO_Attainment for Unit Tests'!C22 -> MAINDARGE SIDDHI PRASAD | F23: 23 | G23: 23
B24: 11 | C24: ='CO_Attainment for Unit Tests'!B23 -> 2201180051 | D24: ='CO_Attainment for Unit Tests'!C23 -> BHOSALE VAISHNAVI DAYANAND | F24: 22 | G24: 23
B25: 12 | C25: ='CO_Attainment for Unit Tests'!B24 -> 2201180052 | D25: ='CO_Attainment for Unit Tests'!C24 -> ATTAR SANIYA VAJIR | F25: 23 | G25: 23
... B69: 56 | C69: ='CO_Attainment for Unit Tests'!B68 -> 2201180419 | D69: ='CO_Attainment for Unit Tests'!C68 -> MULE SNEHA SANJIVAN | F69: 24 | G69: 24
B70: 57 | C70: ='CO_Attainment for Unit Tests'!B69 -> 23510250259 | D70: ='CO_Attainment for Unit Tests'!C69 -> BANSODE VINAYAK BABRUWAN
B71: 58 | C71: ='CO_Attainment for Unit Tests'!B70 -> 23510250260 | D71: ='CO_Attainment for Unit Tests'!C70 -> ISHWARI ASHOK HAWALE
B72: 59 | C72: ='CO_Attainment for Unit Tests'!B71 -> 23510250261 | D72: ='CO_Attainment for Unit Tests'!C71 -> JADHAV SANJYOT SHYAM | F72: 22 | G72: 23
B73: 60 | C73: ='CO_Attainment for Unit Tests'!B72 -> 23510250262 | D73: ='CO_Attainment for Unit Tests'!C72 -> KANLOD SHUBHAM GANPAT | F73: 15 | G73: 22
B74: 61 | C74: ='CO_Attainment for Unit Tests'!B73 -> 23510250263 | D74: ='CO_Attainment for Unit Tests'!C73 -> PHULARI VISHVJEET UMESH | F74: 16 | G74: 23
B75: 62 | C75: ='CO_Attainment for Unit Tests'!B74 -> 23510250264 | D75: ='CO_Attainment for Unit Tests'!C74 -> VHOTTE SHRUTIKA VAIJNATH
B76: 63
B77: 64
B78: 65
B79: 66
B80: 67
B81: 68
B82: 69
B83: 70
B84: 71
B85: 72
B86: 73
B87: 74
... B96: 83
...

Sheet CO_attainment for Indirect
C1: Indirect Assessment through Course end Survey
C4: Course Name : | D4: ='CO_attain_SLA_FA-PR_SA-PR'!D4 -> Data Structures Using _C
C5: Course Code : | D5: ='CO_attain_SLA_FA-PR_SA-PR'!D5 -> 22317
C6: Program/Semester : | D6: ='CO_attain_SLA_FA-PR_SA-PR'!D6 -> 3rd SEM(CO3I SCHEME)
C7: Academic Year: | D7: ='CO_attain_SLA_FA-PR_SA-PR'!D7 -> 2023-24
B9: * Rating Scale : 5-Excellent, 4-Very good, 3- Good, 2-poor, 1-Very Poor
B10: Sr. No. | C10: Enrollment ID | D10: Student Name | E10: # Course Exit Survey of students ( * Rating Scale )
E14: 5
B15: 1 | C15: ='CO_attainment for FA-TH ESE'!C14 -> 2201180002 | D15: ='CO_attainment for FA-TH ESE'!D14 -> GARAD ANJALI NITIN | E15: 0
C16: ='CO_attainment for FA-TH ESE'!#REF! -> #ERROR! | D16: ='CO_attainment for FA-TH ESE'!#REF! -> #ERROR!
B17: 2 | C17: ='CO_attainment for FA-TH ESE'!#REF! -> #ERROR! | D17: ='CO_attainment for FA-TH ESE'!#REF! -> #ERROR!
C18: ='CO_attainment for FA-TH ESE'!#REF! -> #ERROR! | D18: ='CO_attainment for FA-TH ESE'!#REF! -> #ERROR!
B19: 3 | C19: ='CO_attainment for FA-TH ESE'!#REF! -> #ERROR! | D19: ='CO_attainment for FA-TH ESE'!#REF! -> #ERROR!
C20: ='CO_attainment for FA-TH ESE'!#REF! -> #ERROR! | D20: ='CO_attainment for FA-TH ESE'!#REF! -> #ERROR!
C21: ='CO_attainment for FA-TH ESE'!#REF! -> #ERROR! | D21: ='CO_attainment for FA-TH ESE'!#REF! -> #ERROR!
B22: 4 | C22: ='CO_attainment for FA-TH ESE'!#REF! -> #ERROR! | D22: ='CO_attainment for FA-TH ESE'!#REF! -> #ERROR!
C23: ='CO_attainment for FA-TH ESE'!#REF! -> #ERROR! | D23: ='CO_attainment for FA-TH ESE'!#REF! -> #ERROR!
C24: ='CO_attainment for FA-TH ESE'!#REF! -> #ERROR! | D24: ='CO_attainment for FA-TH ESE'!#REF! -> #ERROR!
C25: ='CO_attainment for FA-TH ESE'!#REF! -> #ERROR! | D25: ='CO_attainment for FA-TH ESE'!#REF! -> #ERROR!
C26: ='CO_attainment for FA-TH ESE'!#REF! -> #ERROR! | D26: ='CO_attainment for FA-TH ESE'!#REF! -> #ERROR!
C27: ='CO_attainment for FA-TH ESE'!#REF! -> #ERROR! | D27: ='CO_attainment for FA-TH ESE'!#REF! -> #ERROR!
C28: ='CO_attainment for FA-TH ESE'!#REF! -> #ERROR! | D28: ='CO_attainment for FA-TH ESE'!#REF! -> #ERROR!
C29: ='CO_attainment for FA-TH ESE'!#REF! -> #ERROR! | D29: ='CO_attainment for FA-TH ESE'!#REF! -> #ERROR!
C30: ='CO_attainment for FA-TH ESE'!#REF! -> #ERROR! | D30: ='CO_attainment for FA-TH ESE'!#REF! -> #ERROR!
B31: 5 | C31: ='CO_attainment for FA-TH ESE'!#REF! -> #ERROR! | D31: ='CO_attainment for FA-TH ESE'!#REF! -> #ERROR!
C32: ='CO_attainment for FA-TH ESE'!#REF! -> #ERROR! | D32: ='CO_attainment for FA-TH ESE'!#REF! -> #ERROR!
C33: ='CO_attainment for FA-TH ESE'!#REF! -> #ERROR! | D33: ='CO_attainment for FA-TH ESE'!#REF! -> #ERROR!
C34: ='CO_attainment for FA-TH ESE'!#REF! -> #ERROR! | D34: ='CO_attainment for FA-TH ESE'!#REF! -> #ERROR!
C35: ='CO_attainment for FA-TH ESE'!#REF! -> #ERROR! | D35: ='CO_attainment for FA-TH ESE'!#REF! -> #ERROR!
C36: ='CO_attainment for FA-TH ESE'!#REF! -> #ERROR! | D36: ='CO_attainment for FA-TH ESE'!#REF! -> #ERROR!
C37: ='CO_attainment for FA-TH ESE'!#REF! -> #ERROR! | D37: ='CO_attainment for FA-TH ESE'!#REF! -> #ERROR!
B38: 6 | C38: ='CO_attainment for FA-TH ESE'!#REF! -> #ERROR! | D38: ='CO_attainment for FA-TH ESE'!#REF! -> #ERROR!
C39: ='CO_attainment for FA-TH ESE'!#REF! -> #ERROR! | D39: ='CO_attainment for FA-TH ESE'!#REF! -> #ERROR!
C40: ='CO_attainment for FA-TH ESE'!#REF! -> #ERROR! | D40: ='CO_attainment for FA-TH ESE'!#REF! -> #ERROR!
C41: ='CO_attainment for FA-TH ESE'!#REF! -> #ERROR! | D41: ='CO_attainment for FA-TH ESE'!#REF! -> #ERROR!
C42: ='CO_attainment for FA-TH ESE'!#REF! -> #ERROR! | D42: ='CO_attainment for FA-TH ESE'!#REF! -> #ERROR!
C43: ='CO_attainment for FA-TH ESE'!#REF! -> #ERROR! | D43: ='CO_attainment for FA-TH ESE'!#REF! -> #ERROR!
C44: ='CO_attainment for FA-TH ESE'!#REF! -> #ERROR! | D44: ='CO_attainment for FA-TH ESE'!#REF! -> #ERROR!
C45: ='CO_attainment for FA-TH ESE'!#REF! -> #ERROR! | D45: ='CO_attainment for FA-TH ESE'!#REF! -> #ERROR!
C46: ='CO_attainment for FA-TH ESE'!#REF! -> #ERROR! | D46: ='CO_attainment for FA-TH ESE'!#REF! -> #ERROR!
...

Sheet CO_PO Mapping Attainment 
F1: CO -PO Attainment
C4: Set Corelation of CO-PO Mapping
C5: Strength of corelation : 3 - high (Substantial), 2- medium, 1- low
B6: Sr. No. | C6: CO | E6: PO | O6: PSO
E7: PO1 | F7: PO2 | G7: PO3 | H7: PO4 | I7: PO5 | J7: PO6 | K7: PO7 | L7: PO8 | M7: PO9 | N7: PO10 | O7: PSO1 | P7: PSO2
E8: Basic Knowledge | F8: Discipline Knowledge | G8: Experiments and Practice | H8: Engineering tools | I8: The Engineer and Society | J8: Environment and Sustainability | K8: Ethics | L8: Individual and Team work | M8: Communication | N8: Life-long learning | O8: Modern software Usage | P8: Measurement of mechanical equipments
B9: 1 | C9: CO1 | D9: Apply the laws of thermodynamics to devices based on thermodynamics | E9: 3 | F9: 3 | G9: 2 | H9: 2 | I9: 2 | J9: 2 | K9: 2 | L9: 2 | M9: 2 | N9: 3 | O9: 3 | P9: 2
B10: 2 | C10: CO2 | D10: Use first law of thermodynamic for ideal gas in closed systems | E10: 3 | F10: 3 | G10: 1 | H10: 2 | I10: 2 | J10: 2 | K10: 2 | L10: 2 | M10: 2 | N10: 1 | O10: 2 | P10: 2
B11: 3 | C11: CO3 | D11: Use relevant steam boilers | E11: 3 | F11: 3 | G11: 2 | H11: 2 | I11: 2 | J11: 3 | K11: 2 | L11: 3 | M11: 2 | N11: 2 | O11: 2 | P11: 2
B12: 4 | C12: CO4 | D12: Use relevant steam nozzles and turbines | E12: 3 | F12: 3 | G12: 2 | H12: 3 | I12: 3 | J12: 2 | K12: 3 | L12: 2 | M12: 2 | N12: 3 | O12: 2 | P12: 2
B13: 5 | C13: CO5 | D13: Use relevant steam condensers | E13: 3 | F13: 3 | G13: 3 | H13: 3 | I13: 2 | J13: 2 | K13: 1 | L13: 3 | M13: 2 | N13: 2 | O13: 3 | P13: 3
B14: 6 | C14: CO6 | D14: Use suitable modes for heat transfer | E14: 3 | F14: 3 | G14: 2 | H14: 2 | I14: 1 | J14: 2 | K14: 1 | L14: 1 | M14: 2 | N14: 1 | O14: 2 | P14: 2
B15: Contribution to PO | E15: =ROUNDUP(AVERAGE(E9:E14),2) -> 3 | F15: =ROUNDUP(AVERAGE(F9:F14),2) -> 3 | G15: =ROUNDUP(AVERAGE(G9:G14),2) -> 2 | H15: =ROUNDUP(AVERAGE(H9:H14),2) -> 2.34 | I15: =ROUNDUP(AVERAGE(I9:I14),2) -> 2 | J15: =ROUNDUP(AVERAGE(J9:J14),2) -> 2.17 | K15: =ROUNDUP(AVERAGE(K9:K14),2) -> 1.84 | L15: =ROUNDUP(AVERAGE(L9:L14),2) -> 2.17 | ... P15: =ROUNDUP(AVERAGE(P9:P14),2) -> 2.17
B16: Course-PO attainment | E16: =ROUNDUP((E15*2.66)/3,2) -> 2.66 | F16: =ROUNDUP((F15*2.66)/3,2) -> 2.66 | G16: =ROUNDUP((G15*2.66)/3,2) -> 1.78 | H16: =ROUNDUP((H15*2.66)/3,2) -> 2.08 | I16: =ROUNDUP((I15*2.66)/3,2) -> 1.78 | J16: =ROUNDUP((J15*2.66)/3,2) -> 1.93 | K16: =ROUNDUP((K15*2.66)/3,2) -> 1.64 | L16: =ROUNDUP((L15*2.66)/3,2) -> 1.93 | ... P16: =ROUNDUP((P15*2.66)/3,2) -> 1.93
B17: % Course-PO attainment | E17: =ROUNDUP((E16/3)*100,2) -> 88.67 | F17: =ROUNDUP((F16/3)*100,2) -> 88.67 | G17: =ROUNDUP((G16/3)*100,2) -> 59.34 | H17: =ROUNDUP((H16/3)*100,2) -> 69.34 | I17: =ROUNDUP((I16/3)*100,2) -> 59.34 | J17: =ROUNDUP((J16/3)*100,2) -> 64.34 | K17: =ROUNDUP((K16/3)*100,2) -> 54.67 | L17: =ROUNDUP((L16/3)*100,2) -> 64.34 | ... P17: =ROUNDUP((P16/3)*100,2) -> 64.34

Sheet Overall CO attainment (2)
E1: Overall CO Attainment
C3: Course Name : | D3: ='CO_attainment for Indirect'!D4 -> Data Structures Using _C
C4: Course Code : | D4: ='CO_attainment for Indirect'!D5 -> 22317
C5: Program/Semester : | D5: ='CO_attainment for Indirect'!D6 -> 3rd SEM(CO3I SCHEME)
C6: Academic Year: | D6: ='CO_attain_SLA_FA-PR_SA-PR'!D7 -> 2023-24
C8: Overall Course CO Attainment
C9: Final Direct Course Attainment Calculation | I9: Final Indirect Course Attainment Calculation
C10: COS | D10: Internal | H10: External
D11: Unit Tests | E11: PA_Term Work | F11: Micro- Project | G11: PR-ESE | H11: E.S.E Board | I11: Course Exit Survey
C12: CO1 | D12: ='CO_Attainment for Unit Tests'!D109 -> 0 | E12: ='CO_attain_SLA_FA-PR_SA-PR'!C111 -> 3 | F12: ='CO_attain_SLA_FA-PR_SA-PR'!C110 -> 0 | G12: ='CO_attain_SLA_FA-PR_SA-PR'!C112 -> 3 | H12: ='CO_attainment for FA-TH ESE'!C110 -> 3 | I12: ='CO_attainment for Indirect'!C91 -> 0
C13: CO2 | D13: ='CO_Attainment for Unit Tests'!E109 -> 0 | E13: =$E12 -> 3 | F13: =$F12 -> 0 | G13: =$G12 -> 3 | H13: =$H12 -> 3 | I13: =$I12 -> 0
C14: CO3 | D14: ='CO_Attainment for Unit Tests'!F109 -> 0 | E14: =$E13 -> 3 | F14: =$F13 -> 0 | G14: =$G13 -> 3 | H14: =$H13 -> 3 | I14: =$I13 -> 0
C15: CO4 | D15: ='CO_Attainment for Unit Tests'!G109 -> 0 | E15: =$E14 -> 3 | F15: =$F14 -> 0 | G15: =$G14 -> 3 | H15: =$H14 -> 3 | I15: =$I14 -> 0
C16: CO5 | D16: ='CO_Attainment for Unit Tests'!H109 -> 0 | E16: =$E15 -> 3 | F16: =$F15 -> 0 | G16: =$G15 -> 3 | H16: =$H15 -> 3 | I16: =$I15 -> 0
C17: CO6 | D17: ='CO_Attainment for Unit Tests'!I109 -> 0 | E17: =$E16 -> 3 | F17: =$F16 -> 0 | G17: =$G16 -> 3 | H17: =$H16 -> 3 | I17: =$I16 -> 0
C18: Average Attainment | D18: =ROUND(AVERAGE(D12:D17),2) -> 0 | E18: =ROUND(AVERAGE(E12:E17),2) -> 3 | F18: =ROUND(AVERAGE(F12:F17),2) -> 0 | G18: =ROUND(AVERAGE(G12:G17),2) -> 3 | H18: =ROUND(AVERAGE(H12:H17),2) -> 3 | I18: =ROUND(AVERAGE(I12:I17),2) -> 0
C19: Indiviual Weightage (%) | D19: 10 | E19: 10 | F19: 10 | G19: 10 | H19: 60 | I19: 100
C20: Direct Total Attainment | D20: =D18*D19/100 -> 0 | E20: =E18*E19/100 -> 0.3 | F20: =F18*F19/100 -> 0 | G20: =G18*G19/100 -> 0.3 | H20: =H18*H19/100 -> 1.8 | I20: =I18*I19/100 -> 0
C21: Total Direct Course Attainment | H21: =SUM(D20:H20) -> 2.4 | I21: Total Indirect Course Attainment | J21: =I20 -> 0
C22: Overall Weightage | H22: 0.8 | I22: Weightage | J22: 0.2
C23: Final Direct Course Attainment | H23: =0.8*H21 -> 1.92 | I23: Final Indirect Course Attainment | J23: =0.2*J21 -> 0
C24: Overall Course CO Attainment (B) | I24: =ROUNDUP(H23+J23,2) -> 1.92
G30: Template sheet is Prepared by Prof. A.B.Bhure
G31: L.M.E., P.L.G.P. Latur

Sheet Overall CO attainment
E1: Overall CO Attainment
C3: Course Name : | D3: ='CO_attainment for Indirect'!D4 -> Data Structures Using _C
C4: Course Code : | D4: ='CO_attainment for Indirect'!D5 -> 22317
C5: Program/Semester : | D5: ='CO_attainment for Indirect'!D6 -> 3rd SEM(CO3I SCHEME)
C6: Academic Year: | D6: ='CO_attain_SLA_FA-PR_SA-PR'!D7 -> 2023-24
C8: DIRECT CO ASSESSMENT TOOL/COURSE EVALUATION PLAN | E8: TH-PA | H8: PR-PA | I8: PR-ESE | J8: TH-ESE | K8: TOTAL
E9: U.Test I | F9: U. Test II | G9: Microproject | H9: PA_Term Work | I9: Practical Exam | J9: E.S.E Board
C10: MAX MARKS AS PER TEACHING SCHEME | E10: 20 | G10: 10 | H10: 25 | I10: 25 | J10: 70 | K10: =SUM(E10:J10) -> 150
C11: INDIVIDUAL WEIGHTAGE (%) | E11: =(E10/$K10)*100 -> 13.333333 | G11: =(G10/$K10)*100 -> 6.6666667 | H11: =(H10/$K10)*100 -> 16.666667 | I11: =(I10/$K10)*100 -> 16.666667 | J11: =(J10/$K10)*100 -> 46.666667 | K11: =SUM(E11:J11) -> 100
C15: Overall Course CO Attainment
C16: Final Direct Course Attainment Calculation
C17: COS | E17: Internal | H17: External
D18: Unit Tests | E18: PA_Term Work | F18: Micro- Project | G18: PR-ESE | H18: E.S.E Board
C19: CO1 | D19: ='CO_Attainment for Unit Tests'!D109 -> 0 | E19: ='CO_attain_SLA_FA-PR_SA-PR'!C111 -> 3 | F19: ='CO_attain_SLA_FA-PR_SA-PR'!C110 -> 0 | G19: ='CO_attain_SLA_FA-PR_SA-PR'!C112 -> 3 | H19: ='CO_attainment for FA-TH ESE'!C110 -> 3
C20: CO2 | D20: ='CO_Attainment for Unit Tests'!E109 -> 0 | E20: =$E19 -> 3 | F20: =$F19 -> 0 | G20: =$G19 -> 3 | H20: =$H19 -> 3
C21: CO3 | D21: ='CO_Attainment for Unit Tests'!F109 -> 0 | E21: =$E20 -> 3 | F21: =$F20 -> 0 | G21: =$G20 -> 3 | H21: =$H20 -> 3
C22: CO4 | D22: ='CO_Attainment for Unit Tests'!G109 -> 0 | E22: =$E21 -> 3 | F22: =$F21 -> 0 | G22: =$G21 -> 3 | H22: =$H21 -> 3
C23: CO5 | D23: ='CO_Attainment for Unit Tests'!H109 -> 0 | E23: =$E22 -> 3 | F23: =$F22 -> 0 | G23: =$G22 -> 3 | H23: =$H22 -> 3
C24: CO6 | D24: ='CO_Attainment for Unit Tests'!I109 -> 0 | E24: =$E23 -> 3 | F24: =$F23 -> 0 | G24: =$G23 -> 3 | H24: =$H23 -> 3
C25: Average Attainment | D25: =ROUND(AVERAGE(D19:D24),2) -> 0 | E25: =ROUND(AVERAGE(E19:E24),2) -> 3 | F25: =ROUND(AVERAGE(F19:F24),2) -> 0 | G25: =ROUND(AVERAGE(G19:G24),2) -> 3 | H25: =ROUND(AVERAGE(H19:H24),2) -> 3
C26: Indiviual Weightage (%) | D26: =E11 -> 13.333333 | E26: =H11 -> 16.666667 | F26: =G11 -> 6.6666667 | G26: =I11 -> 16.666667 | H26: =J11 -> 46.666667
C27: Direct Total Attainment | D27: =D25*D26/100 -> 0 | E27: =E25*E26/100 -> 0.5 | F27: =F25*F26/100 -> 0 | G27: =G25*G26/100 -> 0.5 | H27: =H25*H26/100 -> 1.4
C28: Total Direct Course Attainment | H28: =SUM(D27:H27) -> 2.4
C29: Overall Weightage | H29: 1
C30: Final Direct Course Attainment | H30: =H29*H28 -> 2.4
C31: Overall Course CO Attainment (B) | I31: =H30+J30 -> 2.4
H34: Name of Faculty & Signature
H35: GOVERNMENT POLYTECHNIC DHARASHIV

Sheet CO_PO Mapping Attainment_PO7
E1: CO -PO Actual Attainment
C2: Course Name : | D2: ='Overall CO attainment'!D3 -> Data Structures Using _C
C3: Course Code : | D3: ='Overall CO attainment'!D4 -> 22317
C4: Program/Scheme-MSBTE Inst.code : | D4: ='Overall CO attainment'!D5 -> 3rd SEM(CO3I SCHEME)
C5: Academic Year: | D5: ='Overall CO attainment'!D6 -> 2023-24
B8: Strength of correlation : 3 - high (Substantial), 2- medium(moderate), 1- low, No relation : '-'
B9: Sr. No. | C9: CO | E9: PO | L9: PSO
E10: PO1 | F10: PO2 | G10: PO3 | H10: PO4 | I10: PO5 | J10: PO6 | K10: PO7 | L10: PSO1 | M10: PSO2
E11: Basic Knowledge & Discipline Knowledge | F11: Problem analysis | G11: Design/developmet of solutions | H11: Engineering tools, Experimentation and Testing | I11: Engineering Practices for society, sustainability , Environment, Ethics | J11: Project Management | K11: Life Long learning | L11: Computer Software and Hardware Usage | M11: Computer Engineering Maintenance
B12: ='PO Set Target attain level'!B20 -> 1 | C12: ='PO Set Target attain level'!C20 -> CO1 | D12: ='PO Set Target attain level'!D20 -> Perform basic operations on arrays | E12: ='PO Set Target attain level'!E20 | F12: ='PO Set Target attain level'!F20 | G12: ='PO Set Target attain level'!G20 | H12: ='PO Set Target attain level'!H20 | I12: ='PO Set Target attain level'!I20 | ... M12: ='PO Set Target attain level'!M20
B13: ='PO Set Target attain level'!B21 -> 2 | C13: ='PO Set Target attain level'!C21 -> CO2 | D13: ='PO Set Target attain level'!D21 -> Apply different searching and sorting techniques. | E13: ='PO Set Target attain level'!E21 | F13: ='PO Set Target attain level'!F21 | G13: ='PO Set Target attain level'!G21 | H13: ='PO Set Target attain level'!H21 | I13: ='PO Set Target attain level'!I21 | ... M13: ='PO Set Target attain level'!M21
B14: ='PO Set Target attain level'!B22 -> 3 | C14: ='PO Set Target attain level'!C22 -> CO3 | D14: ='PO Set Target attain level'!D22 -> Implement basic operations on stack and queue using array representation | E14: ='PO Set Target attain level'!E22 | F14: ='PO Set Target attain level'!F22 | G14: ='PO Set Target attain level'!G22 | H14: ='PO Set Target attain level'!H22 | I14: ='PO Set Target attain level'!I22 | ... M14: ='PO Set Target attain level'!M22
B15: ='PO Set Target attain level'!B23 -> 4 | C15: ='PO Set Target attain level'!C23 -> CO4 | D15: ='PO Set Target attain level'!D23 -> Implement basic operations on Linked List | E15: ='PO Set Target attain level'!E23 | F15: ='PO Set Target attain level'!F23 | G15: ='PO Set Target attain level'!G23 | H15: ='PO Set Target attain level'!H23 | I15: ='PO Set Target attain level'!I23 | ... M15: ='PO Set Target attain level'!M23
B16: ='PO Set Target attain level'!B24 -> 5 | C16: ='PO Set Target attain level'!C24 -> CO5 | D16: ='PO Set Target attain level'!D24 -> Implement program to create and traverse tree to solve problems | F16: ='PO Set Target attain level'!F24 | G16: ='PO Set Target attain level'!G24 | H16: ='PO Set Target attain level'!H24 | I16: ='PO Set Target attain level'!I24 | J16: ='PO Set Target attain level'!J24 | K16: ='PO Set Target attain level'!K24 | L16: ='PO Set Target attain level'!L24 | M16: ='PO Set Target attain level'!M24
B17: Average Contribution of each CO to each PO (A) | E17: =IFERROR(AVERAGE(E12:E16),0) -> 0 | F17: =IFERROR(AVERAGE(F12:F16),0) -> 0 | G17: =IFERROR(AVERAGE(G12:G16),0) -> 0 | H17: =IFERROR(AVERAGE(H12:H16),0) -> 0 | I17: =IFERROR(AVERAGE(I12:I16),0) -> 0 | J17: =IFERROR(AVERAGE(J12:J16),0) -> 0 | K17: =IFERROR(AVERAGE(K12:K16),0) -> 0 | L17: =IFERROR(AVERAGE(L12:L16),0) -> 0 | M17: =IFERROR(AVERAGE(M12:M16),0) -> 0
B18: Course CO-PO ACTUAL ATTAINMENT LEVEL= ((AxB)/3) | E18: =E17*'Overall CO attainment'!I31/3 -> 0 | F18: =F17*'Overall CO attainment'!I31/3 -> 0 | G18: =G17*'Overall CO attainment'!I31/3 -> 0 | H18: =H17*'Overall CO attainment'!I31/3 -> 0 | I18: =I17*'Overall CO attainment'!I31/3 -> 0 | J18: =J17*'Overall CO attainment'!I31/3 -> 0 | K18: =K17*'Overall CO attainment'!I31/3 -> 0 | L18: =L17*'Overall CO attainment'!I31/3 -> 0 | M18: =M17*'Overall CO attainment'!I31/3 -> 0
B19: % Course-PO attainment | E19: =ROUNDUP((E18/3)*100,2) -> 0 | F19: =ROUNDUP((F18/3)*100,2) -> 0 | G19: =ROUNDUP((G18/3)*100,2) -> 0 | H19: =ROUNDUP((H18/3)*100,2) -> 0 | I19: =ROUNDUP((I18/3)*100,2) -> 0 | J19: =ROUNDUP((J18/3)*100,2) -> 0 | K19: =ROUNDUP((K18/3)*100,2) -> 0 | L19: =ROUNDUP((L18/3)*100,2) -> 0 | M19: =ROUNDUP((M18/3)*100,2) -> 0
J22: Name of Faculty & Signature
J23: GOVERNMENT POLYTECHNIC DHARASHIV
